Workbook
Name RatingLabel: #REF!
Name RatingLabels: #REF!
Name RatingLabelss: #REF!
Name Table: #REF!

Sheet Rating Guide
A3: Privacy Risk and Document Assessment Request (PRADAR)
B5: PRADAR is a 5-in-1 tool that helps your organization to: (1) Build a scalable Privacy Management Program (PMP) (2) Identify gaps in your current PMP (3) Assess PMP maturity; (4) Provide a Data Privacy and Accountability Compliance Framework (5) Act as a Document Request List
B7: Compliance Levels (Per item)
B8: To assess the organization’s privacy practices against legislation and best-practice standards, we use a standardized four-level compliance scoring system: 1 (Not Compliant) to 4 (Fully Compliant) based on the NPC 3rd Toolkit. This ensures consistent evaluation and reporting across all compliance areas.
B9: 1 | C9: Not Compliant | D9: No documented evidence or practice
B10: 2 | C10: Partially Compliant | D10: No documented evidence but there is evidence of practice (initiative)
B11: 3 | C11: Substantially Compliant | D11: Documented evidence exists, but practice is inconsistent
B12: 4 | C12: Fully Compliant | D12: Evidence is documented and in practice
B14: Maturity Levels (Overall)
B15: These Maturity Levels are patterned on the OAIC Privacy Foundational Self-Assessment Tool and the NIST Privacy Risk Management Framework. They help assess an organization’s current privacy practices and guide the development or improvement of privacy procedures and systems, enabling systematic evaluation and enhancement of each program element for greater consistency, scalability, and compliance.
B16: 1 | C16: Initial | D16: Your organization is just beginning to consider privacy processes, with informal, reactive, and ad hoc practices that are not aligned with organizational priorities or objectives.
B17: 2 | C17: Commencing | D17: Your organization is aware of privacy risks and considers them in decision-making, practices are approved yet not implemented organization-wide, though they align with priorities and risk assessments.
B18: 3 | C18: Developing | D18: Your organization has established strong privacy processes in some areas, while others need development. Policies are formal, approved, and regularly updated based on risks and objectives.
B19: 4 | C19: Refining | D19: Your organization meets most or all foundational privacy processes outlined in this tool. Practices evolve through lessons learned, emerging risks, and advanced technologies, supporting continuous improvement.

Sheet Scoreboard 
B2: Status as of | C2: =TODAY() -> 45985
B3: Overall Maturity Level | C3: =AVERAGE(Table13456[[Average Rating ]]) -> #DIV/0! | D3: =IF(ROUNDDOWN(C3,0)=1,'Rating Guide'!C$16,IF(ROUNDDOWN(C3,0)=2,'Rating Guide'!C$17,IF(ROUNDDOWN(C3,0)=3,'Rating Guide'!C$18,IF(ROUNDDOWN(C3,0)=4,'Rating Guide'!C$19, "")))) -> #DIV/0! | E3: =IF(ROUNDDOWN(C3,0)=1,'Rating Guide'!D$16,IF(ROUNDDOWN(C3,0)=2,'Rating Guide'!D$17,IF(ROUNDDOWN(C3,0)=3,'Rating Guide'!D$18,IF(ROUNDDOWN(C3,0)=4,'Rating Guide'!D$19, "")))) -> #DIV/0! | J3: Initial - the organization are just beginning to consider privacy processes in the business. It is recommended, that the organization focus on implementing the recommendations in the Privacy Management Plan Tool and other resources to establish foundational privacy practices. | K3: Commencing - the organization have some privacy processes in place, but they are not systematically embedded across all areas of the business. It is recommended, that the organization needs to prioritise the recommendations to build a consistent approach to privacy management. | L3: Developing - This indicates that the organization have established some strong privacy processes while others need development. It is recommended, that the organization work through the remaining recommendations and begin considering the improvements suggested. | M3: Refining - This indicates that the organization are meeting most or all of the foundational privacy processes for businesses outlined in this tool It is recommended, that the organization work through the remaining recommendations and begin considering the improvements suggested.
B5: Summary of Compliance Ratings per Domain
B6: Privacy Domains | C6: Average Rating | D6: Compliance | E6: Description
B7: Establish Data Privacy Governance | C7: =AVERAGEIF(PRADAR!D4:D27,Table13456[[#This Row],[Privacy Domains]],PRADAR!P4:P27) -> #DIV/0! | D7: =IF(ROUNDDOWN(C7,0)=1,'Rating Guide'!C$9,IF(ROUNDDOWN(C7,0)=2,'Rating Guide'!C$10,IF(ROUNDDOWN(C7,0)=3,'Rating Guide'!C$11,IF(ROUNDDOWN(C7,0)=4,'Rating Guide'!C$12, "")))) -> #DIV/0! | E7: =IF(ROUNDDOWN(C7,0)=1,'Rating Guide'!D$9,IF(ROUNDDOWN(C7,0)=2,'Rating Guide'!D$10,IF(ROUNDDOWN(C7,0)=3,'Rating Guide'!D$11,IF(ROUNDDOWN(C7,0)=4,'Rating Guide'!D$12, "")))) -> #DIV/0!
B8: Privacy Risk Assessment | C8: =AVERAGEIF(PRADAR!D5:D27,Table13456[[#This Row],[Privacy Domains]],PRADAR!P5:P27) -> #DIV/0! | D8: =IF(ROUNDDOWN(C8,0)=1,'Rating Guide'!C$9,IF(ROUNDDOWN(C8,0)=2,'Rating Guide'!C$10,IF(ROUNDDOWN(C8,0)=3,'Rating Guide'!C$11,IF(ROUNDDOWN(C8,0)=4,'Rating Guide'!C$12, "")))) -> #DIV/0! | E8: =IF(ROUNDDOWN(C8,0)=1,'Rating Guide'!D$9,IF(ROUNDDOWN(C8,0)=2,'Rating Guide'!D$10,IF(ROUNDDOWN(C8,0)=3,'Rating Guide'!D$11,IF(ROUNDDOWN(C8,0)=4,'Rating Guide'!D$12, "")))) -> #DIV/0!
B9: Maintain Organization Commitment | C9: =AVERAGEIF(PRADAR!D6:D27,Table13456[[#This Row],[Privacy Domains]],PRADAR!P6:P27) -> #DIV/0! | D9: =IF(ROUNDDOWN(C9,0)=1,'Rating Guide'!C$9,IF(ROUNDDOWN(C9,0)=2,'Rating Guide'!C$10,IF(ROUNDDOWN(C9,0)=3,'Rating Guide'!C$11,IF(ROUNDDOWN(C9,0)=4,'Rating Guide'!C$12, "")))) -> #DIV/0! | E9: =IF(ROUNDDOWN(C9,0)=1,'Rating Guide'!D$9,IF(ROUNDDOWN(C9,0)=2,'Rating Guide'!D$10,IF(ROUNDDOWN(C9,0)=3,'Rating Guide'!D$11,IF(ROUNDDOWN(C9,0)=4,'Rating Guide'!D$12, "")))) -> #DIV/0!
B10: Privacy and Data Protection in day to day Operations | C10: =AVERAGEIF(PRADAR!D7:D27,Table13456[[#This Row],[Privacy Domains]],PRADAR!P7:P27) -> #DIV/0! | D10: =IF(ROUNDDOWN(C10,0)=1,'Rating Guide'!C$9,IF(ROUNDDOWN(C10,0)=2,'Rating Guide'!C$10,IF(ROUNDDOWN(C10,0)=3,'Rating Guide'!C$11,IF(ROUNDDOWN(C10,0)=4,'Rating Guide'!C$12, "")))) -> #DIV/0! | E10: =IF(ROUNDDOWN(C10,0)=1,'Rating Guide'!D$9,IF(ROUNDDOWN(C10,0)=2,'Rating Guide'!D$10,IF(ROUNDDOWN(C10,0)=3,'Rating Guide'!D$11,IF(ROUNDDOWN(C10,0)=4,'Rating Guide'!D$12, "")))) -> #DIV/0!
B11: Manage Security Risk | C11: =AVERAGEIF(PRADAR!D8:D27,Table13456[[#This Row],[Privacy Domains]],PRADAR!P8:P27) -> #DIV/0! | D11: =IF(ROUNDDOWN(C11,0)=1,'Rating Guide'!C$9,IF(ROUNDDOWN(C11,0)=2,'Rating Guide'!C$10,IF(ROUNDDOWN(C11,0)=3,'Rating Guide'!C$11,IF(ROUNDDOWN(C11,0)=4,'Rating Guide'!C$12, "")))) -> #DIV/0! | E11: =IF(ROUNDDOWN(C11,0)=1,'Rating Guide'!D$9,IF(ROUNDDOWN(C11,0)=2,'Rating Guide'!D$10,IF(ROUNDDOWN(C11,0)=3,'Rating Guide'!D$11,IF(ROUNDDOWN(C11,0)=4,'Rating Guide'!D$12, "")))) -> #DIV/0!
B12: Data Breach Management | C12: =AVERAGEIF(PRADAR!D9:D28,Table13456[[#This Row],[Privacy Domains]],PRADAR!P9:P28) -> #DIV/0! | D12: =IF(ROUNDDOWN(C12,0)=1,'Rating Guide'!C$9,IF(ROUNDDOWN(C12,0)=2,'Rating Guide'!C$10,IF(ROUNDDOWN(C12,0)=3,'Rating Guide'!C$11,IF(ROUNDDOWN(C12,0)=4,'Rating Guide'!C$12, "")))) -> #DIV/0! | E12: =IF(ROUNDDOWN(C12,0)=1,'Rating Guide'!D$9,IF(ROUNDDOWN(C12,0)=2,'Rating Guide'!D$10,IF(ROUNDDOWN(C12,0)=3,'Rating Guide'!D$11,IF(ROUNDDOWN(C12,0)=4,'Rating Guide'!D$12, "")))) -> #DIV/0!
B13: Manage Third Party Risks | C13: =AVERAGEIF(PRADAR!D10:D29,Table13456[[#This Row],[Privacy Domains]],PRADAR!P10:P29) -> #DIV/0! | D13: =IF(ROUNDDOWN(C13,0)=1,'Rating Guide'!C$9,IF(ROUNDDOWN(C13,0)=2,'Rating Guide'!C$10,IF(ROUNDDOWN(C13,0)=3,'Rating Guide'!C$11,IF(ROUNDDOWN(C13,0)=4,'Rating Guide'!C$12, "")))) -> #DIV/0! | E13: =IF(ROUNDDOWN(C13,0)=1,'Rating Guide'!D$9,IF(ROUNDDOWN(C13,0)=2,'Rating Guide'!D$10,IF(ROUNDDOWN(C13,0)=3,'Rating Guide'!D$11,IF(ROUNDDOWN(C13,0)=4,'Rating Guide'!D$12, "")))) -> #DIV/0!
B14: Human Resources Management | C14: =AVERAGEIF(PRADAR!D11:D30,Table13456[[#This Row],[Privacy Domains]],PRADAR!P11:P30) -> #DIV/0! | D14: =IF(ROUNDDOWN(C14,0)=1,'Rating Guide'!C$9,IF(ROUNDDOWN(C14,0)=2,'Rating Guide'!C$10,IF(ROUNDDOWN(C14,0)=3,'Rating Guide'!C$11,IF(ROUNDDOWN(C14,0)=4,'Rating Guide'!C$12, "")))) -> #DIV/0! | E14: =IF(ROUNDDOWN(C14,0)=1,'Rating Guide'!D$9,IF(ROUNDDOWN(C14,0)=2,'Rating Guide'!D$10,IF(ROUNDDOWN(C14,0)=3,'Rating Guide'!D$11,IF(ROUNDDOWN(C14,0)=4,'Rating Guide'!D$12, "")))) -> #DIV/0!
B15: Continuing Assessment and Development | C15: =AVERAGEIF(PRADAR!D12:D31,Table13456[[#This Row],[Privacy Domains]],PRADAR!P12:P31) -> #DIV/0! | D15: =IF(ROUNDDOWN(C15,0)=1,'Rating Guide'!C$9,IF(ROUNDDOWN(C15,0)=2,'Rating Guide'!C$10,IF(ROUNDDOWN(C15,0)=3,'Rating Guide'!C$11,IF(ROUNDDOWN(C15,0)=4,'Rating Guide'!C$12, "")))) -> #DIV/0! | E15: =IF(ROUNDDOWN(C15,0)=1,'Rating Guide'!D$9,IF(ROUNDDOWN(C15,0)=2,'Rating Guide'!D$10,IF(ROUNDDOWN(C15,0)=3,'Rating Guide'!D$11,IF(ROUNDDOWN(C15,0)=4,'Rating Guide'!D$12, "")))) -> #DIV/0!
B16: Manage Privacy Ecosystem | C16: =AVERAGEIF(PRADAR!D13:D32,Table13456[[#This Row],[Privacy Domains]],PRADAR!P13:P32) -> #DIV/0! | D16: =IF(ROUNDDOWN(C16,0)=1,'Rating Guide'!C$9,IF(ROUNDDOWN(C16,0)=2,'Rating Guide'!C$10,IF(ROUNDDOWN(C16,0)=3,'Rating Guide'!C$11,IF(ROUNDDOWN(C16,0)=4,'Rating Guide'!C$12, "")))) -> #DIV/0! | E16: =IF(ROUNDDOWN(C16,0)=1,'Rating Guide'!D$9,IF(ROUNDDOWN(C16,0)=2,'Rating Guide'!D$10,IF(ROUNDDOWN(C16,0)=3,'Rating Guide'!D$11,IF(ROUNDDOWN(C16,0)=4,'Rating Guide'!D$12, "")))) -> #DIV/0!

Sheet PRADAR
B3: PMP Component | C3: PMP Sub-domain | D3: Privacy Domain | E3: Control Question | F3: DRL No. | G3: Proof of Compliance | H3: Document Link | I3: DRL Status | J3: Basis/Minimun Req | K3: Assessor | L3: Assessment | M3: Assessment Status | N3: Reviewer's Status | O3: Rating Guide | P3: Rating | Q3: Gaps | R3: Client's Comments | S3: Client's Status | T3: Action Plan | U3: Responsible Party | V3: Timeline | W3: Numeric Rating
B4: Organizational Commitment | C4: Management Buy-in | D4: Establish Data Privacy Governance | E4: Does management provide the resources needed to effectively implement your Privacy Management Program (PMP)? | F4: 1 | G4: Budget allocation document/ Resource Allocation Plans | J4: Basis: NPC Circular 2023-06; The budget should be proportionate to the nature of the personal data, the risks involved in processing, the size of the organization, the volume of data processed, and current data privacy best practices in the industry. | O4: Rating 1 – Not Compliant: No budget or resources for the PMP. Management does not provide support. Rating 2 – Partially Compliant: No formal PMP budget. Management provides occasional resources, but allocation is reactive and does not align with risks or best practices. Rating 3 – Substantially Compliant: Documented PMP budget exists, but resource allocation is inconsistent. Resources may not be sufficient or aligned with risks, affecting full implementation. Rating 4 – Fully Compliant: Approved PMP budget is in place. Management provides adequate resources aligned with risks, data volume, and best practices, ensuring full support for the program.
B5: Organizational Commitment | C5: Management Buy-in | D5: Establish Data Privacy Governance | E5: Has management issued a communication or memorandum outlining the organization’s compliance targets to support adherence to the Data Privacy Act of 2012 (DPA)? | F5: 2 | G5: Signed policy or statements of commitment to data privacy, Data privacy implementation plans or compliance roadmaps endorsed by management, or; Meeting minutes showing management discussion or approval of data privacy initiatives. | O5: Rating 1 – Not Compliant: No documented communication from management outlining compliance targets for the DPA, and no informal communication exists. Rating 2 – Partially Compliant: No formal memo, but there are verbal instructions or informal discussions showing management’s intent to meet privacy compliance. Rating 3 – Substantially Compliant: A formal memo exists outlining compliance targets, but practice is inconsistent. The memo may not be fully shared, updated, or supported, leading to partial implementation. Rating 4 – Fully Compliant: Management has issued and shared a clear memo outlining data privacy compliance targets, supported by ongoing initiatives and aligned with the DPA.
B6: Organizational Commitment | C6: Data Protection Officer | D6: Establish Data Privacy Governance | E6: Have you appointed and registered a Data Protection Officer (DPO) with the National Privacy Commission (NPC)? | F6: 3 | G6: Appointment Papers / Contract of the DPO and/or DPO team (Notarized) | J6: Basis: NPC Circular No. 2022-04 Inaugural DPO must be registered with the NPC within 20 days from effectivity of the appointment. Change in the DPO within ten (10) days from effectivity of the appointment of the new DPO Unless otherwise allowed by law or the Commission, the DPO must be an organic employee of the government agency or private entity. FOR GOVERNMENT AGENCY Must designate and register a DPO according to the rank of its highest official: • Department Secretary or equivalent: DPO rank not lower than Assistant Secretary or Executive Director IV • Undersecretary or equivalent: DPO rank at least Director IV • Assistant Secretary or equivalent: DPO rank at least Director II • Regional Director or equivalent: DPO rank at least Division Chief For Local Government Units (LGUs): • Provincial, City, and Municipal levels must designate a DPO with a rank not lower than Department Head. • Cities and Municipalities may designate a Compliance Officer for Privacy (COP) at the Barangay level, under the supervision of the City or Municipal DPO. | O6: Rating 1 – Not Compliant: No documented appointment or NPC registration of a DPO. Rating 2 – Partially Compliant: A DPO is informally designated, but there is no formal appointment or NPC registration. Rating 3 – Substantially Compliant: A DPO is formally appointed and registered, but may not fully meet eligibility requirements or registration is delayed. Rating 4 – Fully Compliant: A DPO is formally appointed and registered within required timelines. The DPO meets all eligibility criteria, and documentation is complete, up-to-date, and fully compliant. | W6: =IFERROR(VALUE(MID(P6,7,1)),"")
B7: Organizational Commitment | C7: Data Protection Officer | D7: Establish Data Privacy Governance | E7: Is the DPO’s role clearly defined? | F7: 4 | G7: Duties and responsibilities in the Appointment Papers / Contract of the DPO / Privacy Manual | J7: Basis: NPC Advisory No. 2017-01 a. Monitor the organization's compliance with the DPA, its IRR, NPC issuances, and other related laws and policies. b. Oversee the conduct of Privacy Impact Assessments. c. Handle data subject complaints and requests to exercise their rights. d. Manage and report data breaches and security incidents. e. Promote privacy awareness and compliance within the organization. f. Support the development and review of privacy-related policies and programs using a privacy-by-design approach. g. Act as the main contact for data subjects, the NPC, and other authorities on privacy matters. h. Coordinate and seek guidance from the NPC on data privacy and security concerns. | O7: Rating 1 – Not Compliant: No documented DPO role, and no evidence that key responsibilities are being performed. Rating 2 – Partially Compliant: The DPO’s role is not formally documented, but there is evidence of the DPO informally handling some duties. Key responsibilities are not clearly defined or consistently carried out. Rating 3 – Substantially Compliant: The DPO’s role is documented and covers several responsibilities, but implementation is inconsistent. Some duties are irregularly or partially carried out, causing gaps between documentation and practice. Rating 4 – Fully Compliant: The DPO role is clearly documented, covering all key responsibilities. The DPO consistently performs these duties in practice, demonstrating full compliance.
B8: Organizational Commitment | C8: Reporting Mechanisms | D8: Establish Data Privacy Governance | E8: Is there a defined process for reporting privacy issues, incidents, or breaches, along with regular privacy and compliance reports, clearly communicated to all employees? | F8: 5 | G8: Documented Escalation / Reporting Procedure | O8: Rating 1 – Not Compliant: No documented process for reporting privacy issues or breaches. Employees do not know how to report incidents, and there are no clear channels or procedures, leading to unreported or unmanaged issues. Rating 2 – Partially Compliant: A process exists but is informal or ad-hoc. There is no standardized procedure, and employees report incidents through inconsistent or unstructured channels, with limited communication about the process. Rating 3 – Substantially Compliant: A documented process is in place, but it is not consistently implemented. The process may not be fully communicated to all employees, and there are gaps in reporting, escalation, or follow-through. Rating 4 – Fully Compliant: A well-documented and clear process for reporting issues or breaches exists. The process is communicated to all employees, consistently followed, and supports timely escalation and response. Employees are fully aware and use the procedure for reporting incidents.
B9: Program Controls | C9: Records of Processing Activities | D9: Privacy Risk Assessment | E9: Do you have an inventory of all data processing systems (DPS) and activities? | F9: 6 | G9: Records of Processing Activities (RoPA) / Data Processing Systems Inventory | J9: Basis: Section 26(c), IRR Records should include: 1. The purpose of processing personal data, including any future processing or data sharing; 2. A description of the categories of data subjects, personal data, and recipients involved in the processing; 3. General details on data flow within the organization—from collection, processing, and retention to disposal or deletion—including time limits; 4. A summary of the organizational, physical, and technical security measures in place; 5. The name and contact details of the personal information controller, joint controller (if any), representative, and the DPO or other responsible compliance officers. | O9: Rating 1 – Not Compliant: No documented inventory of data processing systems or activities. Rating 2 – Partially Compliant: No formal inventory, but some systems or activities are tracked informally. Records are incomplete and lack required details. Rating 3 – Substantially Compliant: A documented inventory exists, covering some required details, but implementation is inconsistent. Some systems or key details may be missing or not regularly updated. Rating 4 – Fully Compliant: A complete and updated inventory exists, covering all required details. | Q9: =IF(P9="Level 5 (Exemplary Compliance)", "", IF(P9="Level 4 (Strong)", "RoPA and data flows are complete, updated, and accessible, but may lack integration with broader risk management or automation tools.", IF(P9="Level 3 (Developing)", "A formal RoPA is in place with core elements, but records are outdated, incomplete, or not regularly reviewed and not easily auditable.", IF(P9="Level 2 (Emerging)", "An informal or incomplete list exists, but lacks required details and consistency, with no reliable data flow mapping or cross-border data tracking.", IF(P9="Level 1 (Critical)", "No RoPA or personal data inventory exists, and there is no awareness of processing requirements or mapping obligations.", ""))))) | W9: =IFERROR(VALUE(MID(P9,7,1)),"")
B10: Program Controls | C10: Registration | D10: Privacy Risk Assessment | E10: Have you registered your DPS with the NPC and ensured their annual renewal? | F10: 7 | G10: NPC Certificate of Registration and Seal of Registration DPS Registration via NPC Registration System (NPC-RS) | J10: Basis: NPC Circular No. 2022-04 Mandatory Registration: PICs or PIPs with 250 or more employees; PICs or PIPs processing sensitive personal information of 1,000 or more individuals; PICs or PIPs whose processing may pose risks to data subjects’ rights and freedoms; or Those processing data that may likely risk or affect the rights and freedoms of data subjects (e.g., government processing). An application for registration filed must be duly notarized and be accompanied by the following documents: A. For Government Agencies: Special or Office Order, or any similar document, designating or appointing the DPO; B. For Domestic Private Entities: 1. For Corporations: a) duly notarized Secretary’s Certificate authorizing the appointment or designation of the DPO; or any other document demonstrating the validity of the appointment or designation of the DPO, signed by the Head of the Organization, accompanied by a valid document conferring authority to the Head of Organization to designate or appoint persons to positions in the organization. b) Securities and Exchange Commission (SEC) Certificate of Registration. c) certified true copy of latest General Information Sheet. d) valid business permit. 2. One Person Corporation: a) duly notarized Secretary’s Certificate authorizing the appointment or designation of DPO, or (2) any other document that demonstrates the validity of the appointment or designation of DPO signed by the sole director of the One Person Corporation. b) SEC Certificate of Registration c) valid business permit 3. Partnership a) duly notarized Partnership Resolution or Special Power of Attorney authorizing the appointment or designation of DPO, or any other document that demonstrates the validity of the appointment or designation. b) SEC Certificate of Registration. c) valid business permit 4.Sole Proprietorships a) duly notarized document appointing the DPO and signed by the sole proprietor, in case the same should elect to appoint or designate another person as DPO. b) DTI Certificate of Registration. c) valid business permit C Foreign Entity: 1.Authenticated copy or Apostille of Secretary’s Certificate authorizing the appointment or designation of DPO+ English translation if needed 2.Authenticated copy or Apostille of the following documents, with an English translation thereof if in a language other than English, where applicable: a)Latest General Information Sheet or any similar document; b)Registration Certificate (Corporation, Partnership, Sole Proprietorship) or any similar document; c)Valid business permit or any similar document | O10: Rating 1 – Not Compliant: The organization has not registered its DPS with the NPC, and renewals are not done. Rating 2 – Partially Compliant: Some effort is shown, like preparing documents or informal tracking of DPS, but no formal submission to the NPC. Registration may be incomplete, and annual renewals are not done. Rating 3 – Substantially Compliant: The organization has registered its DPS with the NPC and submitted most required documents, but some are outdated or incomplete. Some DPS may be missing, and renewals may not always be on time. Rating 4 – Fully Compliant: All applicable DPS are fully registered with the NPC. All supporting documents are complete and submitted. Annual renewals are done consistently, and records are kept up to date. | Q10: =IF(P10="Level 5 (Exemplary Compliance)", "", IF(P10="Level 4 (Strong)", "A valid NPC Certificate and Seal are in place, properly displayed online and on physical premises, with complete and updated registration records.", IF(P10="Level 3 (Developing)", "A valid NPC Certificate exists, but the Seal is not visibly posted online or onsite, and some registration details may be outdated.", IF(P10="Level 2 (Emerging)", "Registration has been attempted but remains incomplete due to missing documents, incorrect DPO info, or absence of Seal display.", IF(P10="Level 1 (Critical)", "No NPC Certificate or Seal of Registration is available; the organization is not registered with the NPC.", ""))))) | W10: =IFERROR(VALUE(MID(P10,7,1)),"")
B11: Program Controls | C11: Risk Assessment | D11: Privacy Risk Assessment | E11: Do you conduct a Privacy Impact Assessment (PIA) for your DPS? | F11: 8 | G11: PIA Report | J11: Basis: NPC Circular 2023-06; NPC Advisory No. 2017-03 A PIA should be evaluated every year: Provided, that such assessment shall be updated as necessary (e.g., new features or major changes in processing, new regulations, new contracts entered by the PIC, or changes in its PIP). A PIA should be undertaken for every processing system that involves personal data. The PIA shall include the following: A. a data inventory identifying: 1.the amount and type of personal data held by the PIC and its PIP, if any, including records of its own personnel; 2.list of all information repositories holding personal data, including location; 3.type of media used for storing the personal data; 4.risks associated with the processing of personal data; and 5.processing operations for the entire personal data life cycle, from collection to disposal or destruction; B. a systematic description of the personal data being processed or to be processed, including the purposes for such processing, anticipated purposes, and their corresponding lawful bases; C. an assessment of the general data privacy principles in relation to the processing; D. a holistic assessment of the risks to the rights and freedoms of a data subject; and E. an assessment of risks to the confidentiality, integrity, and availability of personal data against any accidental or unlawful destruction, alteration, and disclosure, as well as against any other unlawful processing. The risks identified in the PIA must be addressed by a Control Framework. The contents of a Control Framework shall take into account, among others, the following: A. Nature of the personal data to be protected; B. Risks represented by the processing, the size of the organization, and the volume of personal data being processed; C. Current data privacy best practices in a specific industry; D. Cost of security implementation; and E. Purpose and extent of data sharing or outsourcing agreements and their attendant risks. Must also conduct a PIA on its Off-The-Shelf Software, solutions, or data processing systems. | O11: Rating 1 – Not Compliant: No PIA has been conducted for any DPS. Rating 2 – Partially Compliant: PIAs are done informally or ad-hoc for some systems, but there is no formal documentation or consistent schedule. Key elements are missing or inconsistently applied. Rating 3 – Substantially Compliant: PIAs are documented for most systems and include some required elements, but updates or implementation are inconsistent. Some assessments may be incomplete or outdated. Rating 4 – Fully Compliant: PIAs are conducted for all DPS, including off-the-shelf software and outsourced systems. They are properly documented, reviewed annually, and updated for system changes, new regulations, or features. | Q11: =IF(P11="Level 5 (Exemplary Compliance)", "", IF(P11="Level 4 (Strong)", "All relevant systems have completed PIAs with documented risks and mitigation steps endorsed by key officers.", IF(P11="Level 3 (Developing)", "Some systems have documented PIAs, but coverage is inconsistent, and risk analysis is either lacking or not maintained.", IF(P11="Level 2 (Emerging)", "PIA efforts exist but are limited to informal or incomplete drafts without risk assessment or formal approvals.", IF(P11="Level 1 (Critical)", "No PIA is performed or documented, exposing the organization to unknown privacy risks and regulatory non-compliance.", ""))))) | W11: =IFERROR(VALUE(MID(P11,7,1)),"")
B12: Program Controls | C12: Policies and Procedures | D12: Maintain Organization Commitment | E12: Have you implemented a Privacy Manual / Data Protection Policies? | F12: 9 | G12: Privacy Manual / Data Protection Policies (e.g., Security Policy, Access Control Policy/Security Clearance, Acceptable Use Policy, Password Policy, Business Continuity Plan, Telecommuting, CCTV Policy, Retention Policy, Privacy-By-Design and Privacy-By-Default principles) | J12: Basis: Sec. 26(b)(e), IRR; NPC Privacy 3rd Toolkit p. 82-89 Implement data protection policies covering organizational, physical, and technical security measures. These policies must: • Consider the nature, scope, context, and purpose of processing, as well as risks to data subjects’ rights and freedoms. • Apply data protection principles when determining and performing processing activities. • Ensure only necessary personal data is processed, stored, and accessed. • Clearly define data volume, processing scope, retention period, and access controls. • Require regular documentation, review, evaluation, and updating of privacy and security measures. Privacy Manual Guide 1. Introduction 2. Definition of Terms 3. Scope and Limitations 4. Processing of Personal Data - Collection, Use, Storage, Retention, and Destruction, Access, Disclosure and Sharing 5. Security Measures • Organizational Measures - Conduct of Privacy Impact Assessment (PIA); Designation of the Data Protection Officer (DPO); Functions of the DPO and other responsible personnel; Duty of Confidentiality; Regular trainings/seminars on data privacy and security; Review of the Privacy Manual; Documentation of DPO and organizational compliance activities • Physical Measures - Data format, storage type, and location; Access procedures and monitoring controls; Office/workstation design; Roles and responsibilities of personnel involved in processing; Data transfer procedures (internal and external); Data retention and disposal procedures • Technical Measures - Monitoring for security breaches; Security features of software and applications; Regular testing and evaluation of security measures; Encryption, authentication, and access control procedures 6. Breach and Security Incidents • Establish a Data Breach Response Team (DBRT) • Implement preventive and mitigation measures • Set procedures for data recovery and restoration • Establish a notification protocol • Maintain proper documentation and reporting of incidents and breaches 7. Inquiries and Complaints 8. Effectivity | O12: Rating 1 – Not Compliant: No Privacy Manual or formal data protection policies exist. There is no guidance on security measures or evidence that privacy principles are being applied. Rating 2 – Partially Compliant: Privacy policies or a manual exist informally or partially, but they are incomplete or applied inconsistently. Rating 3 – Substantially Compliant: A Privacy Manual or policies exist, covering most security measures, but implementation is inconsistent. Some areas, like PIAs, breach response, or training, may not be fully implemented or monitored. Rating 4 – Fully Compliant: A comprehensive Privacy Manual or data protection policies are documented, implemented, and regularly reviewed and updated. Policies are applied in practice. | Q12: =IF(P12="Level 5 (Exemplary)", "", IF(P12="Level 4 (Strong)", "Privacy Manual and complaint process are complete and functional, but not yet embedded into wider risk management practices. Basis: RA 10173 Sec. 21; NPC Circular 2022-04 Sec. 10, 14.", IF(P12="Level 3 (Developing)", "Manual and procedures exist but lack depth, regular use, or accessibility to all data subjects. Basis: RA 10173 Sec. 16 & 21; NPC Circular 2022-04 Sec. 10, 14.", IF(P12="Level 2 (Emerging)", "Manual exists in draft form; complaints procedures are unclear, informal, or lack responsible personnel. Basis: RA 10173 Sec. 21; NPC Advisory 2017-01; NPC Circular 2022-04 Sec. 5, 6.", IF(P12="Level 1 (Critical)", "No privacy documentation or complaint channels exist, resulting in no guidance or recourse for data subjects. Basis: RA 10173 Sec. 16 & 21; NPC Circular 2022-04 Sec. 5, 6, 10, 14.", ""))))) | W12: =IFERROR(VALUE(MID(P12,7,1)),"")
B13: Program Controls | C13: Data Security | D13: Manage Security Risk | E13: Do you implement organizational, physical, and technical security measures to ensure the proper protection of all personal data? | F13: 10 | G13: Data center and storage areas with limited physical access Report on technical security measures and information security tools in place Firewalls implemented Encryption for data transmission and data storage Access policy for onsite, remote, and online access Audit logs maintained Backup solutions in place Report of internal security audits or other internal assessments Certifications or accreditations (e.g., ISO 27001, NPC Privacy Mark) Vulnerability assessments conducted Penetration testing for applications and network Other measures demonstrating compliance | J13: Basis: Sec. 25, IRR Personal information controllers and personal information processors shall implement reasonable and appropriate organizational, physical, and technical security measures for the protection of personal data, taking into account the nature of the personal data to be protected, the risks presented by the processing, the size of the organization and complexity of its operations, current data privacy best practices, cost of security implementation, and the most appropriate standard recognized by the information and communications technology industry, as may be necessary. As minimum, it must comply with the NPC Circular 2023-06. | O13: Rating 1 – Not Compliant: No security measures (organizational, physical, or technical) are in place to protect personal data. Risks related to processing or data sensitivity are not addressed. Rating 2 – Partially Compliant: Some security measures are in place informally, but there is no formal documentation or consistent application. There are gaps in protection, and only certain aspects of security are addressed. Rating 3 – Substantially Compliant: Documented security measures exist, covering organizational, physical, and technical safeguards, but implementation is inconsistent. Some measures (e.g., risk assessments, access controls, encryption, staff awareness) may be incomplete or not fully aligned with data risks or best practices. Rating 4 – Fully Compliant: All security measures (organizational, physical, and technical) are fully documented, implemented, and consistently applied. Measures are proportional to data sensitivity, processing risks, and industry standards. All controls are maintained to protect personal data from unauthorized access, alteration, or disclosure. | Q13: =IF(P13="Level 5 (Exemplary)","", IF(P13="Level 4 (Strong)","Updated and documented policies fully cover Acceptable Use; explained to all relevant users; formal user agreement signed before access.", IF(P13="Level 3 (Developing)","Policies cover most areas and are explained to some users; user agreement obtained inconsistently.", IF(P13="Level 2 (Emerging)","Policies exist but are outdated or incomplete; limited communication; no formal user agreement.", IF(P13="Level 1 (Critical)","No documented Acceptable Use policies; users receive no explanations or agreements.", ""))))) | W13: =IFERROR(VALUE(MID(P13,7,1)),"")
B14: Program Controls | C14: Capacity Building | D14: Human Resources Management | E14: Do you regularly train personnel on privacy and security policies? | F14: 11 | G14: Number of employees who attended privacy and data protection training / Training Attendance Sheet of Commitment to comply with the Data Privacy Act included in the Code of Conduct or a signed document filed in each employee’s record | J14: Basis: Sec. 26(d), IRR; NPC Circular 2023-06 There shall be capacity building, orientation or training programs for employees, agents or representatives, regarding privacy or security policies. Periodically train employees, agents, personnel, or representatives on privacy and data protection policies. | O14: Rating 1 – Not Compliant: No training or orientation on privacy or security policies. Personnel are unaware of data protection requirements. Rating 2 – Partially Compliant: Training is informal or irregular, with no formal schedule or documentation. Some personnel may have received privacy or security guidance, but it is not comprehensive or consistently delivered. Rating 3 – Substantially Compliant: Formal, documented training programs exist, but participation is inconsistent. Some personnel may not have attended, or refresher training may be irregular or incomplete. Rating 4 – Fully Compliant: Regular, documented training is provided for all employees, agents, and representatives. The training covers privacy, security policies, and data protection principles, and is consistently delivered, monitored, and updated according to legal requirements. | Q14: =IF(P14="Level 5 (Exemplary)","", IF(P14="Level 4 (Strong)","Regular, scheduled training programs with documented attendance and materials covering all relevant personnel.", IF(P14="Level 3 (Developing)","Periodic trainings held but attendance and coverage are inconsistent or incomplete.", IF(P14="Level 2 (Emerging)","Training conducted irregularly or only for select employees.", IF(P14="Level 1 (Critical)","No training programs conducted for personnel on privacy and security policies.", ""))))) | W14: =IFERROR(VALUE(MID(P14,7,1)),"")
B15: Program Controls | C15: Capacity Building | D15: Human Resources Management | E15: Do you require Non-Disclosure Agreements (NDAs) and issue Security Clearances for personnel handling personal data? | F15: 12 | G15: NDAs or confidentiality agreements Security Clearance Policy / Access Control Policy (may be in Privacy Manual) | J15: Basis: Sec. 26(d), IRR; NPC Circular 2023-06 Employees, agents, or representatives shall operate and hold personal data under strict confidentiality if the personal data are not intended for public disclosure. This obligation shall continue even after leaving the public service, transferring to another position, or upon terminating their employment or contractual relations. Must ensure that access to personal data is strictly regulated by issuing a security clearance or its equivalent only to its authorized personnel. A copy of the appropriate security clearance or its equivalent must be filed with its DPO. | O15: Rating 1 – Not Compliant: No evidence that personnel handling personal data sign NDAs or have security clearances. Access to personal data is unregulated, and confidentiality is not enforced. Rating 2 – Partially Compliant: NDAs or security clearances are applied informally or inconsistently. Some personnel may have signed agreements, but documentation is incomplete or not consistently enforced. Rating 3 – Substantially Compliant: NDAs and security clearances are documented and issued, but implementation is inconsistent. Some personnel may lack proper authorization, or updates and monitoring of confidentiality obligations are irregular. Rating 4 – Fully Compliant: All personnel handling personal data sign NDAs and are issued security clearances. Documentation is maintained with the DPO, access is strictly controlled, and confidentiality obligations are consistently enforced, even after employment or contract termination, in line with legal requirements.
B16: Program Controls | C16: Capacity Building | D16: Human Resources Management | E16: Is there ongoing training and capacity building for the DPO, and does the DPO pursue certifications and membership in recognized DPO organizations? | F16: 13 | G16: Certificate of Training of DPO Certifications of DPOs | J16: Basis: NPC Privacy 3rd Toolkit p. 126-127 The Commission does not require certifications for key personnel. However, it is considered best practice across jurisdictions for organizations to properly equip their personnel with appropriate trainings that enable them to fulfill their specific roles and functions. Some international certifications or training commonly considered for this purpose include the following -Certified Information Systems Auditor (CISA). -Certified Information Security Manager (CISM) -Certified in the Governance of Enterprise IT (CGEIT). -Certified Information Systems Security Professionals (CISSP) -GIAC Security Essentials (GSEC) -Project Management Professional (PMP) -Certified Information Privacy Manager (CIPM) -Certified Information Privacy Professional (CIPP) -Certified Information Privacy Technologist (CIPT) | O16: Rating 1 – Not Compliant: No evidence of training or professional development for the DPO. The DPO does not pursue certifications or join recognized privacy/security organizations. Rating 2 – Partially Compliant: The DPO participates in some informal or ad-hoc training, but it is not systematic or documented. Pursuit of certifications or memberships is limited or inconsistent, with no formal plan for ongoing development. Rating 3 – Substantially Compliant: Ongoing training and capacity-building are documented and available to the DPO, but participation may be irregular. Some recommended certifications or memberships have not been pursued. Rating 4 – Fully Compliant: The DPO regularly participates in documented training and development programs, actively pursues relevant certifications (e.g., CISA, CISM, CIPM, CIPP), and joins recognized privacy/security organizations. | Q16: =IF(P16="Level 5 (Exemplary)","", IF(P16="Level 4 (Strong)","All employees formally acknowledge DPA compliance with proper documentation and recordkeeping.", IF(P16="Level 3 (Developing)","Most employees have signed but records are incomplete or inconsistently maintained.", IF(P16="Level 2 (Emerging)","Acknowledgment exists but is informal, inconsistently signed, or not properly filed.", IF(P16="Level 1 (Critical)","No documented acknowledgment or commitment to comply with the DPA by employees.", ""))))) | W16: =IFERROR(VALUE(MID(P16,7,1)),"")
B17: Program Controls | C17: Breach Management | D17: Data Breach Management | E17: Have you implemented safeguards to prevent or minimize personal data breaches? | F17: 14 | G17: Schedule of breach drills Number of Trainings conducted for internal personnel on breach management Personnel Order constituting the Data Breach Response Team Incident Response Policy and Procedure (may be in Privacy Manual) | J17: Basis: Sec. 26(d), IRR Regular monitoring for security breaches, and a process both for identifying and accessing reasonably foreseeable vulnerabilities in their computer networks, and for taking preventive, corrective, and mitigating action against security incidents that can lead to a personal data breach Security Incident Management Policy A Personal Information Controller (PIC) or Personal Information Processor (PIP) must have clear policies and procedures for managing security incidents, including personal data breaches. These must ensure: A. Establishment of a Data Breach Response Team with clearly defined roles to ensure timely action during a security incident or breach. B. Implementation of organizational, physical, and technical security measures to prevent or minimize data breaches and enable timely detection of security incidents. C. Adoption of an incident response procedure to contain breaches and restore system integrity. D. Mitigation measures to minimize harm and negative consequences to affected data subjects. E. Compliance with the Data Privacy Act, its IRR, and NPC issuances on breach notification. A Security Incident Management Policy must also include preventive safeguards to reduce the likelihood of data breaches, such as: A. Conducting Privacy Impact Assessments (PIAs) to identify risks in data processing, considering data sensitivity, potential harm, and impact of breaches. B. Establishing a Data Governance Policy to uphold transparency, legitimate purpose, and proportionality. C. Implementing security measures to protect the availability, integrity, and confidentiality of personal data. D. Performing regular monitoring, vulnerability scans, and breach detection on computer networks. E. Ensuring capacity building and training for personnel on data breach management and incident response procedures. F. Regularly reviewing, testing, and evaluating the effectiveness of security policies and procedures. | O17: Rating 1 – Not Compliant: No safeguards or incident response processes for personal data breaches. No Security Incident Management Policy or Data Breach Response Team exists. Rating 2 – Partially Compliant: Some informal or ad-hoc measures exist but are not consistently applied. No formal team or documented process for managing breaches. Rating 3 – Substantially Compliant: A documented Security Incident Management Policy and safeguards exist, covering breach response and monitoring, but implementation is inconsistent. Some key elements may not be fully applied or maintained. Rating 4 – Fully Compliant: Comprehensive safeguards are in place to prevent or minimize personal data breaches. Policies are documented. Security controls are regularly tested, reviewed, and updated to ensure compliance and timely breach response. | Q17: =IF(P17="Level 5 (Exemplary)","", IF(P17="Level 4 (Strong)","DPO regularly participates in updated, relevant training programs; certificates documented and maintained.", IF(P17="Level 3 (Developing)","DPO attends some relevant trainings; records exist but may lack consistency or comprehensiveness.", IF(P17="Level 2 (Emerging)","Occasional or one-time training attended by the DPO without regular updates.", IF(P17="Level 1 (Critical)","No training or capacity-building activities documented for the DPO.", ""))))) | W17: =IFERROR(VALUE(MID(P17,7,1)),"")
B18: Program Controls | C18: Breach Management | D18: Data Breach Management | E18: Do you document security incidents and personal data breaches, and comply with breach notification requirements? | F18: 15 | G18: Record of Security incidents and personal data breaches, including notification for personal data breaches / Annual Security Incident Report (ASIR) | J18: Basis: NPC Circular 2023-06; NPC Breach Reporting All security incidents and personal data breaches shall be documented through written reports, including those not covered by the notification requirements. For other security incidents not involving personal data, a report containing aggregated data shall constitute sufficient documentation. An ASIR must be submitted to the NPC each year. It includes all security incidents and personal data breaches that occurred within the calendar year, even those not subject to mandatory notification. The ASIR must contain: • The total number of incidents and breaches encountered; and • The classification of incidents based on their causes and whether they were mandatory, voluntary, or other security incidents. Following the launch of the Data Breach Notification Management System (DBNMS), all ASIRs must be submitted exclusively through the system. The deadline for submission of the ASIR for the previous calendar year is 31 March of the current year. | O18: Rating 1 – Not Compliant: No documentation of security incidents or personal data breaches. The organization does not comply with ASIR submission or breach notification requirements. Incidents are unrecorded and unreported. Rating 2 – Partially Compliant: Some incidents or breaches are documented, but records are incomplete or inconsistent. ASIRs may be missing required details, and breach notification requirements are only partially met. Rating 3 – Substantially Compliant: Incidents and breaches are documented, and ASIRs are submitted, but there are gaps in classification, coverage, or timeliness. Some incidents may be missing. Rating 4 – Fully Compliant: All incidents and breaches are thoroughly documented, and ASIRs are submitted annually on time. Documentation is complete and accurate. | Q18: =IF(P18="Level 5 (Exemplary)","", IF(P18="Level 4 (Strong)","DPO holds multiple relevant certifications and maintains active membership in recognized privacy or data protection organizations.", IF(P18="Level 3 (Developing)","DPO holds at least one relevant certification or is a member of a recognized privacy/professional organization.", IF(P18="Level 2 (Emerging)","DPO has some informal or unrelated training but no recognized certifications or memberships.", IF(P18="Level 1 (Critical)","DPO has no relevant certifications or memberships.", ""))))) | W18: =IFERROR(VALUE(MID(P18,7,1)),"")
B19: Program Controls | C19: Third-Party Management | D19: Manage Third Party Risks | E19: Do you execute Data Sharing Agreements and review or enter into contracts and other agreements for personal data transfers, including cross-border transfers, to ensure a comparable level of data protection, compliance with the DPA, and security of the transfers? | F19: 16 | G19: Data Sharing Agreements or a similar document Model Contractual Clauses for Cross-Border Transfers of Personal Data if applicable List of recipients of personal data (PIPs, other PICs, service providers, government agencies) | J19: Basis: NPC Circular No. 2020-03; NPC Advisory No. 2024 - 01 Contents of a Data Sharing Agreement A. Purpose and lawful basis B. Objectives C. Parties D. Term E. Operational details F. Security G. Data subjects’ rights H. Retention and Data Disposal Record of data sharing arrangements. — should establish and maintain a record of its data sharing arrangements, including the following: A. Contact details of all parties, including their respective data protection officers; B. Legal bases for the data sharing arrangement/s; C. Copy of the DSA/s, if executed; D. Written, recorded, or electronic proof of the consent obtained from data subjects, where applicable; and E. Date and/or time consent was obtained and withdrawn, where applicable. | O19: Rating 1 – Not Compliant: No agreements or records for personal data transfers. Transfers happen without safeguards or compliance with the DPA. Rating 2 – Partially Compliant: Some agreements exist, but they’re informal or incomplete. Key details may be missing, and records are inconsistent. Rating 3 – Substantially Compliant: Most agreements are documented with key details, but implementation and record-keeping are inconsistent. Some transfers lack full consent or security measures, and cross-border transfers may not ensure full data protection. Rating 4 – Fully Compliant: All transfers, including cross-border, have documented agreements covering all required details. Records are maintained, regularly reviewed, and fully comply with the DPA and relevant regulations. | Q19: =IF(P19="Level 5 (Exemplary)","", IF(P19="Level 4 (Strong)","Formally executed, comprehensive DSAs covering scope, responsibilities, security, and breach notifications; regularly reviewed.", IF(P19="Level 3 (Developing)","DSAs executed for most arrangements; some lack key clauses or are outdated.", IF(P19="Level 2 (Emerging)","DSAs exist but are incomplete, informal, or not executed before sharing begins.", IF(P19="Level 1 (Critical)","No Data Sharing Agreements executed with third parties for personal data sharing.", ""))))) | W19: =IFERROR(VALUE(MID(P19,7,1)),"")
B20: Program Controls | C20: Third-Party Management | D20: Manage Third Party Risks | E20: Do you review or enter into outsourcing contracts with Personal Information Processors (PIPs) to ensure a comparable level of data protection and compliance with the DPA? | F20: 17 | G20: Data Outsourcing / Subcontracting Agreements or formal contracts or other legal acts | J20: Basis: Sec. 44, IRR Contents of a Data Outsourcing/ Subcontracting Agreement A. The subject and duration of the processing; B. The nature and purpose of the processing; C. The type of personal data and categories of data subjects; D. The obligations and rights of the PIC; and E. The geographic location of processing under the subcontracting arrangement. F. The contract or legal act must also require the PIP to: • Process personal data only upon documented instructions from the PIC, including international transfers, unless authorized by law; • Impose confidentiality obligations on all personnel authorized to process personal data; • Implement appropriate security measures and comply with the DPA, its IRR, and NPC issuances; • Avoid engaging another processor without prior approval from the PIC, ensuring equivalent data protection obligations if subcontracting occurs; • Assist the PIC in responding to data subject requests; • Support the PIC’s compliance with the DPA, related laws, and NPC rules, considering the nature of processing; • Delete or return all personal data to the PIC upon completion of services, including deleting copies unless retention is legally authorized; • Provide all necessary information to demonstrate compliance and allow audits or inspections by the PIC or its authorized auditor; and • Inform the PIC immediately if any instruction appears to violate the DPA, its IRR, or NPC issuances. | O20: Rating 1 – Not Compliant: No outsourcing agreements/contracts with PIPs, or existing contracts lack data protection, confidentiality, or DPA compliance provisions. No oversight or monitoring of PIPs. Rating 2 – Partially Compliant: Contracts with PIPs exist, but they are informal, incomplete, or inconsistently applied. Key elements are missing. Limited oversight and monitoring of PIP compliance. Rating 3 – Substantially Compliant: Outsourcing agreements with PIPs are documented and cover most required elements, but implementation or monitoring is inconsistent. Some obligations may not be fully applied. Rating 4 – Fully Compliant: All outsourcing contracts with PIPs are documented, comprehensive, and consistently enforced. PIP activities are regularly monitored and reviewed. | Q20: =IF(P20="Level 5 (Exemplary)","", IF(P20="Level 4 (Strong)","Fully reviewed and executed contracts with Personal Information Processors (PIPs), incorporating DPA compliance, security, confidentiality, breach notification, audit rights, and data disposal clauses; periodic reviews documented.", IF(P20="Level 3 (Developing)","Contracts include most required data protection clauses but lack comprehensive documentation or regular periodic reviews.", IF(P20="Level 2 (Emerging)","Contracts exist but lack explicit DPA compliance clauses or essential data protection provisions.", IF(P20="Level 1 (Critical)","No outsourcing contracts executed or reviewed for compliance with the Data Privacy Act (DPA).", ""))))) | W20: =IFERROR(VALUE(MID(P20,7,1)),"")
B21: Program Controls | C21: Communication | D21: Privacy and Data Protection in day to day Operations | E21: Where personal data is collected, do you provide clear and easily accessible Privacy Notices with the DPO’s contact details? | F21: 18 | G21: Privacy Notice on the website and/or within the organization (where personal data is collected) and CCTV Notice (if applicable) Visible announcement displaying the DPO’s contact details (e.g., on the website or in the Privacy Notice) | J21: Basis: Sec. 18, 34(2), IRR; NPC Advisory No. 2017-01; NPC Circular No. 2023 - 04; NPC Circular No. 2024 – 02 PRIVACY NOTICE Default format: Just-in-time and Layered Notices Just-in-time/Short Privacy Notice: At a minimum, the following information must be clearly stated: (a) a description of the personal data to be processed; (b) the purpose, nature, extent, duration, and scope of processing based on consent; (c) the identity of the PIC; (d) the data subject’s rights and how these rights can be exercised. Full Privact Notice: The data subject must be informed about how their personal data is collected and processed, including its purpose, scope, risks, safeguards, and their rights. All information must be easy to access and written in clear, plain language. The Privacy Notice must include: (a) Description of the personal data collected; (b) Purpose of processing, including for marketing, profiling, or research; (c) Legal basis for processing, if not based on consent; (d) Scope and method of processing; (e) Recipients or possible recipients of the data; (f) Methods for automated access (if applicable), including the logic, purpose, and effects of such processing; (g) Identity and contact details of the personal data controller or representative; (h) Retention period of the personal data; (i) Risks and safeguards (j) Data subject rights, including access, correction, objection, and the right to file a complaint with the NPC. CCTV NOTICE The requirements above must apply. In addition, PICs must ensure that CCTV notices comply with the following: (a) Information about the use of CCTV systems must be provided in the most suitable format and written in clear, plain, and concise language. (b) CCTV notices must be clearly visible and prominently displayed in appropriate areas, such as entry points or other conspicuous locations. (c) The nature, scope, and extent of surveillance, as well as the purpose, system capabilities, and other relevant details, must be disclosed to data subjects in line with their right to be informed under the DPA. DISPLAY OF DPO'S CONTACT DETAILS The DPO’s contact details must be included in at least the following materials: a. Website b. Privacy Notice c. Privacy Policy d. Privacy Manual or Privacy Guide The DPO’s contact details should include: a. Title or designation b. Postal address c. Dedicated telephone number d. Dedicated email address | O21: Rating 1 – Not Compliant: No privacy notices are provided where personal data is collected, and DPO contact details are missing. Data subjects are not informed of how their data is processed or their rights. Rating 2 – Partially Compliant: Privacy notices are provided in some instances but may lack key information or be difficult to access. DPO contact details may be inconsistent, and notices may not cover all required elements. Rating 3 – Substantially Compliant: Privacy notices are documented and available, covering most required information. Some notices may be inconsistent or incomplete across collection points, and DPO contact details are included in some materials but not all. Rating 4 – Fully Compliant: Clear, accessible privacy notices are provided everywhere personal data is collected, covering all required elements. DPO contact details are consistently included across all required materials, written in plain and understandable language.
B22: Program Controls | C22: Communication | D22: Privacy and Data Protection in day to day Operations | E22: If applicable, do you have a procedure for obtaining consent? | F22: 19 | G22: Procedures for obtaining consent and a Consent Form (may be included in Privacy Manual) | J22: Basis: NPC Circular No. 2023 - 04 The consent form must include all information required in a Privacy Notice and clearly state that consent is the lawful basis for processing. It should present the PIC’s proposal to the data subject, requesting their consent to process personal data under the terms stated in the form. | O22: Rating 1 – Not Compliant: No procedure or consent forms exist. Personal data is processed without informing the data subject or obtaining lawful consent. Rating 2 – Partially Compliant: A procedure or consent form exists but is informal, incomplete, or inconsistently applied. Required details from the Privacy Notice may be missing, or the form may not clearly state consent as the lawful basis. Rating 3 – Substantially Compliant: A documented procedure exists, and forms generally include required information. Implementation is inconsistent, or some forms lack clarity on the lawful basis or processing terms. Rating 4 – Fully Compliant: A formal, documented procedure for obtaining consent is in place. Consent forms include all required information and clearly state consent as the lawful basis. The procedure is consistently applied, ensuring proper data subject information and valid consent.
