Workbook

Sheet Cover Page
D5: [Insert logo]
C10: Privacy Impact Assessment Report In compliance with the Data Privacy Act of 2012
C25: Document Code:
C26: Effective Date:
C27: Review Date:
C28: Version Control No.:

Sheet Project-System Description 
B2: Project-System Description
B3: Description
B4: The system is a | D4: designed to manage | F4: of personal data within
B6: Key Processes include:
B7: Data Collection | C7: Gathering data through
B8: Data Usage | C8: Using data for
B9: Data Storage | C9: Secure storage in
B10: Data Disposal | C10: Secure disposal in line with
B12: If applicable:
B13: The system integrates with existing programs such as
B14: Supported by documents like the Requirements and Design Specifications
B16: Purpose
B17: The system aims to
B19: Scope of the PIA
B20: This Privacy Impact Assessment (PIA) reviews privacy risks in the | G20: related to the | H20: =E4 -> 0 | I20: of personal data.
B21: It examines the data types, legal basis, security,
B22: This PIA does not cover non-data protection issues or activities that do not involve personal data.

Sheet P1 Threshold Analysis
B2: Threshold Analysis
B3: No. | C3: Question | D3: Yes/No | E3: Response
B4: 1 | C4: Does the project or system collect, use, keep, share, or dispose of personal information?
B5: 2 | C5: Does the project or system collect, use, keep, share, or dispose of sensitive personal information or privileged information?
B6: 3 | C6: Is processing regular and not just a one-time thing?
B7: 4 | C7: Does the project or system include information about vulnerable individuals?
B8: 5 | C8: Does the processing involve records of 250 or more individuals?
B9: 6 | C9: Does the processing use off-the-shelf software?
B10: 7 | C10: Are you using individuals’ information for a purpose other than originally intended?
B11: 8 | C11: Will individuals’ information be used for marketing, online services, systematic monitoring, tracking or observing their location or behavior?
B12: 9 | C12: Will individuals’ information be shared with organizations or people who have not previously had regular access to it?
B13: 10 | C13: Does the project or system use new technology that may be seen as privacy-intrusive?
B14: 11 | C14: Will the processing use automated decision making, AI or profiling with legal or similar significant effect?
B15: 12 | C15: Will the processing prevent individuals from exercising a right or using a service or a contract?
C17: IS PIA REQUIRED? | D17: =IF(OR(AND(D4="Yes", COUNTIF(D5:D15, "Yes")>0), AND(D4="No", D5="Yes", COUNTIF(D5:D15, "Yes")>0)), "Yes", "No") -> No | E17: =IF(D17="Yes", "PIA Required - Proceed to the next section", IF(D17="No", "PIA Not Required - Proceed to Sign-Off","")) -> PIA Not Required - Proceed to Sign-Off

Sheet P1 Stakeholder Engagement
B2: Stakeholder(s) Engagement
B3: Name/Position | C3: Role | D3: Involvement | E3: Inputs/ Recommendations

Sheet P2 Data Mapping
B2: Data Processing System Details
B4: Is DPS Manual, Electronic, or Both?
B5: Data Processing System Name
B6: Basis for Processing Personal Information | D6: Basis for Processing Sensitive Personal Information (If applicable)
B8: Purpose of Processing | D8: Intended Future Purpose (if any)
B10: Description of the category or categories of data subject
B12: Type of Personal Data | C12: Categories of Personal Data | D12: Amount of personal data (estimate) | F12: PIP/PIC
B13: Personal Information
B15: Sensitive Personal Information
B17: Privileged Information
B18: Is processing done as PIC or PIP?
B19: Is the system outsourced or subcontracted?
B20: Name of PIP | D20: Email Address | F20: Contact No.
B22: Name of PIC
B24: Name of DPO | D24: Email Address | F24: Contact No.
B26: Is the system a publicly facing online mobile or web-based application?
B27: Is the system External and/or Internal facing?
B28: Is there any notification regarding any automated decision-making operation and/or profiling?
B29: Lawful basis of processing personal data | E29: =IF($D$28="No", "N/A", IF($D$28="Automated decision-making", "Insert details below", IF($D$28="Profiling", "Insert details below", IF($D$28="Both", "Insert details below",""))))
B31: Other relevant information pertaining to the specified lawful basis | E31: =IF($D$28="No", "N/A", IF($D$28="Automated decision-making", "Insert details below", IF($D$28="Profiling", "Insert details below", IF($D$28="Both", "Insert details below",""))))
B33: Is consent used as the basis for processing?
B34: Consent form or any other proof of obtaining consent? (Specify below)
B36: Retention period for the data processed | E36: =IF($D$28="No", "N/A", IF($D$28="Automated decision-making", "Insert details below", IF($D$28="Profiling", "Insert details below", IF($D$28="Both", "Insert details below",""))))
B38: Methods and logic utilized for automated processing | E38: =IF($D$28="No", "N/A", IF($D$28="Automated decision-making", "Insert details below", IF($D$28="Profiling", "Insert details below", IF($D$28="Both", "Insert details below",""))))
B40: Possible decisions relating to the data subject based on the processed data, particularly if they would significantly affect his or her rights and freedoms | E40: =IF($D$28="No", "N/A", IF($D$28="Automated decision-making", "Insert details below", IF($D$28="Profiling", "Insert details below", IF($D$28="Both", "Insert details below",""))))
B42: Description of Security Measures
B43: Organizational
B45: Physical
B47: Technical
B51: General Information of the Data Life Cycle
B53: Collection
B54: When is the personal data collected? | F54: Who collects the personal data? | H54: From whom is the personal data collected?
B58: Use
B59: Position & Department | D59: Scope/Module | G59: File Name | I59: Purpose
B70: Disclosure
B71: Category of recipients to whom the data might be disclosed | C71: Recipients | D71: Data Sharing Purpose | F71: Is there any Data Sharing Agreements with other parties? | H71: Name of PIC | I71: Is the personal data transferred outside of the Philippines?
B72: Internal | D72: N/A | F72: N/A | H72: N/A | I72: N/A
D73: N/A | F73: N/A | H73: N/A | I73: N/A
B74: External
B76: Retention and Disposal
...

Sheet P3 Gen Data Privacy Principles
B2: Note: The default risk rating is based on inherent risk, calculated using data subject impact and likelihood. This rating is not final and may change based on your assessment as the process or system owner. To request a change, consult your Data Protection Officer (DPO). If approved, the rating can be updated.
B5: Transparency
B6: No. | C6: Questions | F6: Yes/No/ N/A | G6: Response | H6: Threats/Vulnerabilities | I6: Risk | J6: Legal Basis | K6: Impact | L6: Probability | M6: Risk Rating
B7: 1 | C7: 1. Are data subjects informed of the following details before or shortly after their personal data is collected (Privacy Notice)? Check all present | H7: =IF(F7="No", "Absence of a comprehensive and timely privacy notice creates a transparency gap, weakening data subjects' ability to make informed decisions and exercise their rights.", "") | I7: =IF(F7="No", "Violation of general privacy principles – Transparency Violation of data subject rights - Rights to be informed", "") | J7: =IF(F7="No", "SEC. 11, DPA SEC. 16(a)(b), DPA", "") | K7: =IF(AND(F7="No", 'P1 Threshold Analysis'!D5="Yes"), 4, IF(AND(F7="No", COUNTIF(F8:F17, "False")>9), 4, IF(AND(F7="No", COUNTIF(F8:F17, "True")>0), 3, ""))) | L7: =IF(AND(F7="No", 'P1 Threshold Analysis'!D5="Yes"), 4, IF(AND(F7="No", COUNTIF(F8:F17, "False")>9), 4, IF(AND(F7="No", COUNTIF(F8:F17, "True")>0), 3, ""))) | M7: =IF(OR(K7="", L7=""), "", IF(K7*L7>=10, IF(K7*L7<=16, "High Risk", ""), IF(K7*L7>=6, IF(K7*L7<=9, "Medium Risk", ""), IF(K7*L7>=2, IF(K7*L7<=4, "Low Risk", ""), IF(K7*L7=1, "Negligible", "")))))
C8: a. Description of the personal data to be processed | F8: FALSE
C9: b. Purposes of processing, including direct marketing, profiling or historical, statistical or scientific purpose if applicable | F9: FALSE
C10: c. Basis of processing, when not based on consent | F10: FALSE
C11: d. Scope and method of processing | F11: FALSE
C12: e. Recipients or categories of recipients who may receive the personal data | F12: FALSE
C13: f. Methods used for automated access (cookie notification), if allowed by the data subject, including the extent of the authorization, the logic involved, and the significance and potential consequences of such processing | F13: FALSE | AZ13: Use of complex or technical language in privacy notices makes it difficult for data subjects to understand how their personal data is processed, increasing the risk of uninformed consent (if processing is based on consent) and non-compliance with transparency obligations.
C14: g. Risks and safeguards involved in the processing | F14: FALSE
C15: h. Identity and contact details of the PIC (your organization) or its representative (DPO) | F15: FALSE
C16: i. Retention period | F16: FALSE
C17: j. Data subject rights and the process for exercising them | F17: FALSE
B18: 2 | C18: Is information and communication about personal data processing easy to access and understand, using clear and plain language (Privacy Notice)? | H18: =IF(F18="No", "Use of complex or technical language in privacy notices makes it difficult for data subjects to understand how their personal data is processed, increasing the risk of uninformed consent and non-compliance with transparency obligations.", "N/A") -> N/A | I18: =IF(F18="No","Violation of general privacy principles – Transparency", "") | J18: =IF(F18="No","SEC. 11, DPA ", "") | K18: =IF(AND(F7="No", COUNTIF(F8:F17, "False")>9), 4, IF(AND(F18="No", 'P1 Threshold Analysis'!D5="Yes"), 3, IF(AND(F18="No", COUNTIF(F8:F17, "FALSE")>0, 'P1 Threshold Analysis'!D4="Yes", 'P1 Threshold Analysis'!D5="No"), 2, ""))) | L18: =IF(AND(F7="No", COUNTIF(F8:F17, "False")>9), 4, IF(AND(F18="No", 'P1 Threshold Analysis'!D5="Yes"), 3, IF(AND(F18="No", COUNTIF(F8:F17, "FALSE")>0, 'P1 Threshold Analysis'!D4="Yes", 'P1 Threshold Analysis'!D5="No"), 2, ""))) | M18: =IF(OR(K18="", L18=""), "", IF(K18*L18>=10, IF(K18*L18<=16, "High Risk", ""), IF(K18*L18>=6, IF(K18*L18<=9, "Medium Risk", ""), IF(K18*L18>=2, IF(K18*L18<=4, "Low Risk", ""), IF(K18*L18=1, "Negligible", "")))))
B19: Legitimate Purpose / Lawfulness
B20: 1 | C20: Is the processing of personal data compatible with a declared and specified purpose which are not contrary to law, morals, or public policy? | H20: =IF(F20="No", "Processing personal data for purposes that are incompatible with the declared purpose and contrary to law, morals, or public policy may lead to regulatory sanctions, reputational damage, and loss of public trust.", "") | I20: =IF(F20="No", "Violation of general privacy principles – Legitimate Purpose", "") | J20: =IF(F20="No", " SEC. 11, DPA", "") | K20: =IF(AND(F20="No", 'P1 Threshold Analysis'!D5="Yes"),4, IF(AND(F20="No", 'P1 Threshold Analysis'!D4="Yes"), 3,"")) | L20: =IF(AND(F20="No", 'P1 Threshold Analysis'!D5="Yes"),4, IF(AND(F20="No", 'P1 Threshold Analysis'!D4="Yes"), 3,"")) | M20: =IF(OR(K20="", L20=""), "", IF(K20*L20>=10, IF(K20*L20<=16, "High Risk", ""), IF(K20*L20>=6, IF(K20*L20<=9, "Medium Risk", ""), IF(K20*L20>=2, IF(K20*L20<=4, "Low Risk", ""), IF(K20*L20=1, "Negligible", "")))))
B21: 2 | C21: Is the processing based on Section 4 (for special cases), Section 12 (for personal information), or Section 13 (for sensitive and privileged information) of the DPA? | H21: =IF(F21="No", "Processing personal data without a valid legal basis under Sections 4, 12, or 13 of the Data Privacy Act exposes the organization to legal liabilities, and penalties.", "") | I21: =IF(F21="No", "Violation of general privacy principles – Legitimate Purpose", "") | J21: =IF(F21="No", " SEC. 11, DPA", "") | K21: =IF(AND(F21="No", 'P1 Threshold Analysis'!D5="Yes"),4, IF(AND(F21="No", 'P1 Threshold Analysis'!D4="Yes"), 3,"")) | L21: =IF(AND(F21="No", 'P1 Threshold Analysis'!D5="Yes"),4, IF(AND(F21="No", 'P1 Threshold Analysis'!D4="Yes"), 3,"")) | M21: =IF(OR(K21="", L21=""), "", IF(K21*L21>=10, IF(K21*L21<=16, "High Risk", ""), IF(K21*L21>=6, IF(K21*L21<=9, "Medium Risk", ""), IF(K21*L21>=2, IF(K21*L21<=4, "Low Risk", ""), IF(K21*L21=1, "Negligible", "")))))
B22: Proportionality / Data minimization
B23: Personal Data/Functions | D23: Adequate (enough to fulfil the purpose) | E23: Relevant & Suitable (related & appropriate) | F23: Necessary | G23: Remarks | H23: Threats/Vulnerabilities | I23: Risk | J23: Legal Basis | K23: Impact | L23: Probability | M23: Risk Rating
B24: Name, Age | D24: No | E24: No | F24: Required | H24: =IF(OR(D24="No", E24="No", F24="No", F24="Optional"), "For Collection Form" & CHAR(10) & "Collecting excessive or irrelevant data increases the risk of misuse, breaches, and non-compliance with data minimization." & CHAR(10) & CHAR(10) & "For Off-the-Shelf Software" & CHAR(10) & "Pre-enabled features may process data without a lawful basis, risking unauthorized use.", "") -> For Collection Form Collecting excessive or irrelevant data increases the risk of misuse, breaches, and non-compliance with data minimization. For Off-the-Shelf Software Pre-enabled features may process data without a lawful basis, risking unauthorized use. | I24: =IF(OR(D24="No", E24="No", F24="No", F24="Optional"), "Violation of general privacy principles – Proportionality / Data Minimization" & CHAR(10) & CHAR(10) & "For Off-the-Shelf Software" & CHAR(10) & "Violation of general privacy principles – Proportionality / Data Minimization / Privacy-by-Design / Privacy-by-Default", "") -> Violation of general privacy principles – Proportionality / Data Minimization For Off-the-Shelf Software Violation of general privacy principles – Proportionality / Data Minimization / Privacy-by-Design / Privacy-by-Default | J24: =IF(OR(D24="No", E24="No", F24="Optional"), "SEC. 11, DPA ", "") -> SEC. 11, DPA | K24: =IF(AND('P1 Threshold Analysis'!D5="Yes", OR(D24="No", E24="No", F24="No", F24="Optional")), 4, IF(AND('P1 Threshold Analysis'!D4="Yes", OR(D24="No", E24="No", F24="No", F24="Optional")), 3, "")) | L24: =IF(AND('P1 Threshold Analysis'!D5="Yes", OR(D24="No", E24="No", F24="No", F24="Optional")), 4, IF(AND('P1 Threshold Analysis'!D4="Yes", OR(D24="No", E24="No", F24="No", F24="Optional")), 3, "")) | M24: =IF(OR(K24="", L24=""), "", IF(K24*L24>=10, IF(K24*L24<=16, "High Risk", ""), IF(K24*L24>=6, IF(K24*L24<=9, "Medium Risk", ""), IF(K24*L24>=2, IF(K24*L24<=4, "Low Risk", ""), IF(K24*L24=1, "Negligible", "")))))
H25: =IF(OR(D25="No", E25="No", F25="No", F25="Optional"), "For Collection Form" & CHAR(10) & "Collecting excessive or irrelevant data increases the risk of misuse, breaches, and non-compliance with data minimization." & CHAR(10) & CHAR(10) & "For Off-the-Shelf Software" & CHAR(10) & "Pre-enabled features may process data without a lawful basis, risking unauthorized use.", "") | I25: =IF(OR(D25="No", E25="No", F25="No", F25="Optional"), "Violation of general privacy principles – Proportionality / Data Minimization" & CHAR(10) & CHAR(10) & "For Off-the-Shelf Software" & CHAR(10) & "Violation of general privacy principles – Proportionality / Data Minimization / Privacy-by-Design / Privacy-by-Default", "") | J25: =IF(OR(D25="No", E25="No", F25="No", F25="Optional"), "SEC. 11, DPA ", "") | K25: =IF(AND('P1 Threshold Analysis'!D5="Yes", OR(D25="No", E25="No", F25="No", F25="Optional")), 4, IF(AND('P1 Threshold Analysis'!D4="Yes", OR(D25="No", E25="No", F25="No", F25="Optional")), 3, "")) | L25: =IF(AND('P1 Threshold Analysis'!D5="Yes", OR(D25="No", E25="No", F25="No", F25="Optional")), 4, IF(AND('P1 Threshold Analysis'!D4="Yes", OR(D25="No", E25="No", F25="No", F25="Optional")), 3, "")) | M25: =IF(OR(K25="", L25=""), "", IF(K25*L25>=10, IF(K25*L25<=16, "High Risk", ""), IF(K25*L25>=6, IF(K25*L25<=9, "Medium Risk", ""), IF(K25*L25>=2, IF(K25*L25<=4, "Low Risk", ""), IF(K25*L25=1, "Negligible", "")))))
H26: =IF(OR(D26="No", E26="No", F26="No", F26="Optional"), "For Collection Form" & CHAR(10) & "Collecting excessive or irrelevant data increases the risk of misuse, breaches, and non-compliance with data minimization." & CHAR(10) & CHAR(10) & "For Off-the-Shelf Software" & CHAR(10) & "Pre-enabled features may process data without a lawful basis, risking unauthorized use.", "") | I26: =IF(OR(D26="No", E26="No", F26="No", F26="Optional"), "Violation of general privacy principles – Proportionality / Data Minimization" & CHAR(10) & CHAR(10) & "For Off-the-Shelf Software" & CHAR(10) & "Violation of general privacy principles – Proportionality / Data Minimization / Privacy-by-Design / Privacy-by-Default", "") | J26: =IF(OR(D26="No", E26="No", F26="No", F26="Optional"), "SEC. 11, DPA ", "") | K26: =IF(AND('P1 Threshold Analysis'!D5="Yes", OR(D26="No", E26="No", F26="No", F26="Optional")), 4, IF(AND('P1 Threshold Analysis'!D4="Yes", OR(D26="No", E26="No", F26="No", F26="Optional")), 3, "")) | L26: =IF(AND('P1 Threshold Analysis'!D5="Yes", OR(D26="No", E26="No", F26="No", F26="Optional")), 4, IF(AND('P1 Threshold Analysis'!D4="Yes", OR(D26="No", E26="No", F26="No", F26="Optional")), 3, "")) | M26: =IF(OR(K26="", L26=""), "", IF(K26*L26>=10, IF(K26*L26<=16, "High Risk", ""), IF(K26*L26>=6, IF(K26*L26<=9, "Medium Risk", ""), IF(K26*L26>=2, IF(K26*L26<=4, "Low Risk", ""), IF(K26*L26=1, "Negligible", "")))))
H27: =IF(OR(D27="No", E27="No", F27="No", F27="Optional"), "For Collection Form" & CHAR(10) & "Collecting excessive or irrelevant data increases the risk of misuse, breaches, and non-compliance with data minimization." & CHAR(10) & CHAR(10) & "For Off-the-Shelf Software" & CHAR(10) & "Pre-enabled features may process data without a lawful basis, risking unauthorized use.", "") | I27: =IF(OR(D27="No", E27="No", F27="No", F27="Optional"), "Violation of general privacy principles – Proportionality / Data Minimization" & CHAR(10) & CHAR(10) & "For Off-the-Shelf Software" & CHAR(10) & "Violation of general privacy principles – Proportionality / Data Minimization / Privacy-by-Design / Privacy-by-Default", "") | J27: =IF(OR(D27="No", E27="No", F27="No", F27="Optional"), "SEC. 11, DPA ", "") | K27: =IF(AND('P1 Threshold Analysis'!D5="Yes", OR(D27="No", E27="No", F27="No", F27="Optional")), 4, IF(AND('P1 Threshold Analysis'!D4="Yes", OR(D27="No", E27="No", F27="No", F27="Optional")), 3, "")) | L27: =IF(AND('P1 Threshold Analysis'!D5="Yes", OR(D27="No", E27="No", F27="No", F27="Optional")), 4, IF(AND('P1 Threshold Analysis'!D4="Yes", OR(D27="No", E27="No", F27="No", F27="Optional")), 3, "")) | M27: =IF(OR(K27="", L27=""), "", IF(K27*L27>=10, IF(K27*L27<=16, "High Risk", ""), IF(K27*L27>=6, IF(K27*L27<=9, "Medium Risk", ""), IF(K27*L27>=2, IF(K27*L27<=4, "Low Risk", ""), IF(K27*L27=1, "Negligible", "")))))
H28: =IF(OR(D28="No", E28="No", F28="No", F28="Optional"), "For Collection Form" & CHAR(10) & "Collecting excessive or irrelevant data increases the risk of misuse, breaches, and non-compliance with data minimization." & CHAR(10) & CHAR(10) & "For Off-the-Shelf Software" & CHAR(10) & "Pre-enabled features may process data without a lawful basis, risking unauthorized use.", "") | I28: =IF(OR(D28="No", E28="No", F28="No", F28="Optional"), "Violation of general privacy principles – Proportionality / Data Minimization" & CHAR(10) & CHAR(10) & "For Off-the-Shelf Software" & CHAR(10) & "Violation of general privacy principles – Proportionality / Data Minimization / Privacy-by-Design / Privacy-by-Default", "") | J28: =IF(OR(D28="No", E28="No", F28="No", F28="Optional"), "SEC. 11, DPA ", "") | K28: =IF(AND('P1 Threshold Analysis'!D5="Yes", OR(D28="No", E28="No", F28="No", F28="Optional")), 4, IF(AND('P1 Threshold Analysis'!D4="Yes", OR(D28="No", E28="No", F28="No", F28="Optional")), 3, "")) | L28: =IF(AND('P1 Threshold Analysis'!D5="Yes", OR(D28="No", E28="No", F28="No", F28="Optional")), 4, IF(AND('P1 Threshold Analysis'!D4="Yes", OR(D28="No", E28="No", F28="No", F28="Optional")), 3, "")) | M28: =IF(OR(K28="", L28=""), "", IF(K28*L28>=10, IF(K28*L28<=16, "High Risk", ""), IF(K28*L28>=6, IF(K28*L28<=9, "Medium Risk", ""), IF(K28*L28>=2, IF(K28*L28<=4, "Low Risk", ""), IF(K28*L28=1, "Negligible", "")))))
B29: Fairness
B30: 1 | C30: Is the Privacy Notice / Consent Form presented objectively and neutrally, without deceptive or manipulative language or design? | H30: =IF(F30="No", "The use of biased or manipulative language in the Privacy Notice/Consent Form undermines the clarity of consent, potentially leading to invalid consent and non-compliance with data protection regulations. ", "") | I30: =IF(F30="No", "Violation of general privacy principles – Fairness ", "") | J30: =IF(F30="No", "SEC. 11, DPA ", "") | K30: =IF(AND(F30="No", 'P1 Threshold Analysis'!D5="Yes"), 4, IF(AND(F30="No", 'P1 Threshold Analysis'!D4="Yes"),3,"")) | L30: =IF(AND(F30="No", 'P1 Threshold Analysis'!D5="Yes"), 4, IF(AND(F30="No", 'P1 Threshold Analysis'!D4="Yes"),3,"")) | M30: =IF(OR(K30="", L30=""), "", IF(K30*L30>=10, IF(K30*L30<=16, "High Risk", ""), IF(K30*L30>=6, IF(K30*L30<=9, "Medium Risk", ""), IF(K30*L30>=2, IF(K30*L30<=4, "Low Risk", ""), IF(K30*L30=1, "Negligible", "")))))
B31: Data Quality / Accuracy
B32: 1 | C32: Is personal data accurate, and kept up to date? Check all present | H32: =IF(F32="No", "Inaccurate or outdated personal data can lead to incorrect decisions, harm to data subjects, and non-compliance with data accuracy requirements, undermining the integrity of the processing system. ", "") | I32: =IF(F32="No", "Violation of general privacy principles – Accuracy ", "") | J32: =IF(F32="No", "SEC. 11, DPA ", "") | K32: =IF(AND(F32="No", 'P1 Threshold Analysis'!D5="Yes"), 4, IF(AND(F32="No", 'P1 Threshold Analysis'!D4="Yes"),3,"")) | L32: =IF(AND(F32="No", 'P1 Threshold Analysis'!D5="Yes"), 4, IF(AND(F32="No", 'P1 Threshold Analysis'!D4="Yes"),3,"")) | M32: =IF(OR(K32="", L32=""), "", IF(K32*L32>=10, IF(K32*L32<=16, "High Risk", ""), IF(K32*L32>=6, IF(K32*L32<=9, "Medium Risk", ""), IF(K32*L32>=2, IF(K32*L32<=4, "Low Risk", ""), IF(K32*L32=1, "Negligible", "")))))
C33: a. Verify data at collection | F33: FALSE
C34: b. Review and update personal data regularly | F34: FALSE
C35: c. Allow users to update their personal data securely | F35: FALSE
C36: d. Use reliable sources when updating records | F36: FALSE
B37: 2 | C37: Is inaccurate or incomplete data rectified, supplemented, destroyed or their further processing restricted? Check all present | H37: =IF(F37="No", "Failure to rectify or restrict processing of inaccurate or incomplete data compromises data quality and may result in violations of data subjects’ rights. ", "") | I37: =IF(F37="No", "Violation of general privacy principles – Accuracy ", "") | J37: =IF(F37="No", "SEC. 11, DPA ", "") | K37: =IF(AND(F37="No", 'P1 Threshold Analysis'!D5="Yes"), 4, IF(AND(F37="No", 'P1 Threshold Analysis'!D4="Yes"),3,"")) | L37: =IF(AND(F37="No", 'P1 Threshold Analysis'!D5="Yes"), 4, IF(AND(F37="No", 'P1 Threshold Analysis'!D4="Yes"),3,"")) | M37: =IF(OR(K37="", L37=""), "", IF(K37*L37>=10, IF(K37*L37<=16, "High Risk", ""), IF(K37*L37>=6, IF(K37*L37<=9, "Medium Risk", ""), IF(K37*L37>=2, IF(K37*L37<=4, "Low Risk", ""), IF(K37*L37=1, "Negligible", "")))))
C38: a. People can request corrections and erasure easily | F38: FALSE
C39: b. Data processing restrictions of inaccurate or incomplete data until rectified | F39: FALSE
C40: c. Secure disposal methods | F40: FALSE
B41: Purpose limitation
B42: 1 | C42: Is personal data collected for specified purpose not further processed in a manner that is incompatible with that purpose? Note: may be further processed for historical, statistical, or scientific purposes, and stored longer as allowed by law, provided appropriate security measures safeguard the data subject’s rights and freedoms. | H42: =IF(F42="No", "Processing personal data for unspecified or incompatible purposes increases the risk of unauthorized use, undermining data subject trust and exposing the organization to regulatory penalties. ", "") | I42: =IF(F42="No", "Violation of general privacy principles – Purpose Limitation Unlawful Processing - Processing of Personal Data for Unauthorized Purposes ", "") | J42: =IF(F42="No", "SEC. 11, DPA SEC. 28, DPA ", "") | K42: =IF(AND(F42="No", 'P1 Threshold Analysis'!D5="Yes"), 4, IF(AND(F42="No", 'P1 Threshold Analysis'!D4="Yes"),3,"")) | L42: =IF(AND(F42="No", 'P1 Threshold Analysis'!D5="Yes"), 4, IF(AND(F42="No", 'P1 Threshold Analysis'!D4="Yes"),3,"")) | M42: =IF(OR(K42="", L42=""), "", IF(K42*L42>=10, IF(K42*L42<=16, "High Risk", ""), IF(K42*L42>=6, IF(K42*L42<=9, "Medium Risk", ""), IF(K42*L42>=2, IF(K42*L42<=4, "Low Risk", ""), IF(K42*L42=1, "Negligible", "")))))
B43: Storage Limitation
...

Sheet P3 Data Subject Rights
B2: Limitations. Data subject rights must be exercised reasonably and may be limited for public interest, protecting other rights, or when processing data for:
B3: 1 | C3: Scientific and statistical research
B4: 2 | C4: Investigation in relation to any criminal, administrative, or tax liabilities of a data subject
B5: 3 | C5: In the interest of national security, rights of data subjects nay be limited pursuant to laws, rules and regulations, or order of a competent court.
B6: 4 | C6: Limitations on the exercise of data subject rights may be applied to analogous cases where the PIC has a legitimate purpose justifying such limitation.
B8: Rights to be informed (Included under the Transparency Principle)
B9: Right to object (Applicable if the processing is based on consent or legitimate interest)
B10: No. | C10: Questions | F10: Yes/No/N/A | H10: Response | I10: Threats/Vulnerabilities | J10: Risk | K10: Legal Basis | L10: Impact | M10: Probability | N10: Risk Rating
B11: 1 | C11: (For consent) Do you obtain the data subject’s consent, evidenced by written, electronic, or recorded means, before processing their personal data? | I11: =IF(F11="No", "Failing to obtain consent in a verifiable form exposes the organization to legal risks, as consent may be challenged, leading to invalid consent and potential non-compliance with data protection laws.", "") | J11: =IF(F11="No", "Unlawful Processing - Unauthorized Processing of Personal Data","") | K11: =IF(F11="No", "SEC. 25, DPA", "") | L11: =IF(AND(F11="No", 'P1 Threshold Analysis'!D5="Yes"), 4, IF(AND(F11="No", 'P1 Threshold Analysis'!D5="No"),3,"")) | M11: =IF(AND(F11="No", 'P1 Threshold Analysis'!D5="Yes"), 4, IF(AND(F11="No", 'P1 Threshold Analysis'!D5="No"),3,"")) | N11: =IF(OR(L11="", M11=""), "", IF(L11*M11>=10, IF(L11*M11<=16, "High Risk", ""), IF(L11*M11>=6, IF(L11*M11<=9, "Medium Risk", ""), IF(L11*M11>=2, IF(L11*M11<=4, "Low Risk", ""), IF(L11*M11=1, "Negligible", "")))))
B12: 2 | C12: (For consent) Before obtaining consent, do you provide the following information clearly and concisely in the consent form or Privacy Notice? Check all present | I12: =IF(F12="No", "Inadequate or unclear information in the consent form or Privacy Notice prevents data subjects from making informed decisions, leading to invalid consent and potential non-compliance with data protection laws. ", "") | J12: =IF(F12="No", "Unlawful Processing - Unauthorized Processing of Personal Data Violation of general privacy principles – Transparency ","") | K12: =IF(F12="No", "SEC. 25, DPA SEC. 11, DPA ", "") | L12: =IF(AND(F12="No", COUNTIF(F13:G16, "False")>3), 4, IF(AND(F12="No", 'P1 Threshold Analysis'!D5="Yes", COUNTIF(F13:G16, "True")>0), 4, IF(AND(F12="No", 'P1 Threshold Analysis'!D5="No",COUNTIF(F13:G16, "True")>0), 3, ""))) | M12: =IF(AND(F12="No", COUNTIF(F13:G16, "False")>3), 4, IF(AND(F12="No", 'P1 Threshold Analysis'!D5="Yes", COUNTIF(F13:G16, "True")>0), 4, IF(AND(F12="No", 'P1 Threshold Analysis'!D5="No",COUNTIF(F13:G16, "True")>0), 3, ""))) | N12: =IF(OR(L12="", M12=""), "", IF(L12*M12>=10, IF(L12*M12<=16, "High Risk", ""), IF(L12*M12>=6, IF(L12*M12<=9, "Medium Risk", ""), IF(L12*M12>=2, IF(L12*M12<=4, "Low Risk", ""), IF(L12*M12=1, "Negligible", "")))))
C13: a. Description of the personal data to be processed | F13: FALSE
C14: b. Purpose, nature, extent, duration and scope of processing | F14: FALSE
C15: c. Identity of the PIC | F15: FALSE
C16: d. Data subject rights and the process for exercising them | F16: FALSE
B17: 3 | C17: (For consent) Does the data subject give specific consent for each declared purpose of data processing? If processing serves multiple unrelated purposes, do you provide a list and allow them to choose which ones to consent to? | I17: =IF(F17="No", "Obtaining blanket consent without allowing data subjects to choose specific purposes undermines the validity of consent and increases the risk of unlawful processing.", "") | J17: =IF(F17="No", "Unlawful Processing - Unauthorized Processing of Personal Data Violation of general privacy principles – Transparency ","") | K17: =IF(F17="No", "SEC. 25, DPA SEC. 11, DPA", "") | L17: =IF(AND(F17="No", 'P1 Threshold Analysis'!D5="Yes"), 4, IF(AND(F17="No", 'P1 Threshold Analysis'!D5="No"),3,"")) | M17: =IF(AND(F17="No", 'P1 Threshold Analysis'!D5="Yes"), 4, IF(AND(F17="No", 'P1 Threshold Analysis'!D5="No"),3,"")) | N17: =IF(OR(L17="", M17=""), "", IF(L17*M17>=10, IF(L17*M17<=16, "High Risk", ""), IF(L17*M17>=6, IF(L17*M17<=9, "Medium Risk", ""), IF(L17*M17>=2, IF(L17*M17<=4, "Low Risk", ""), IF(L17*M17=1, "Negligible", "")))))
B18: 4 | C18: Do you inform the data subject of their right to object or withdraw consent to the processing of their personal data? | I18: =IF(F18="No", "Failure to inform data subjects of their right to object or withdraw consent compromises their control over personal data and may result in non-compliance with transparency and consent requirements. ", "") | J18: =IF(F18="No", "Violation of general privacy principles – Transparency Violation of data subject rights - Rights to object ","") | K18: =IF(F18="No", "SEC. 11, DPA SEC. 34(b), IRR ", "") | L18: =IF(AND(F18="No", 'P1 Threshold Analysis'!D5="Yes"), 4, IF(AND(F18="No", 'P1 Threshold Analysis'!D5="No"),3,"")) | M18: =IF(AND(F18="No", 'P1 Threshold Analysis'!D5="Yes"), 4, IF(AND(F18="No", 'P1 Threshold Analysis'!D5="No"),3,"")) | N18: =IF(OR(L18="", M18=""), "", IF(L18*M18>=10, IF(L18*M18<=16, "High Risk", ""), IF(L18*M18>=6, IF(L18*M18<=9, "Medium Risk", ""), IF(L18*M18>=2, IF(L18*M18<=4, "Low Risk", ""), IF(L18*M18=1, "Negligible", "")))))
B19: 5 | C19: Do you inform the data subject of the scope and consequences of withdrawing consent or objecting at the start of processing and upon withdrawal/objection? | I19: =IF(F19="No", "Failing to inform data subjects about the scope and consequences of withdrawing consent or objecting to processing undermines informed decision-making and increases the risk of disputes or complaints. ", "") | J19: =IF(F19="No", "Violation of general privacy principles – Transparency Violation of data subject rights - Rights to object ","") | K19: =IF(F19="No", "SEC. 11, DPA SEC. 34(b), IRR ", "") | L19: =IF(AND(F19="No", 'P1 Threshold Analysis'!D5="Yes"), 4, IF(AND(F19="No", 'P1 Threshold Analysis'!D5="No"),3,"")) | M19: =IF(AND(F19="No", 'P1 Threshold Analysis'!D5="Yes"), 4, IF(AND(F19="No", 'P1 Threshold Analysis'!D5="No"),3,"")) | N19: =IF(OR(L19="", M19=""), "", IF(L19*M19>=10, IF(L19*M19<=16, "High Risk", ""), IF(L19*M19>=6, IF(L19*M19<=9, "Medium Risk", ""), IF(L19*M19>=2, IF(L19*M19<=4, "Low Risk", ""), IF(L19*M19=1, "Negligible", "")))))
B20: 6 | C20: When a data subject objects, do you stop processing their personal data and comply with the objection unless processing is allowed in Section 12 and 13 of the DPA, excluding consent and legitimate interest? | I20: =IF(F20="No", "Continuing to process personal data after a data subject has objected exposes the organization to legal liabilities, regulatory sanctions, and reputational damage, for failing to respect data subject rights. ", "") | J20: =IF(F20="No", "Violation of data subject rights - Rights to object ","") | K20: =IF(F20="No", "SEC. 34(b), IRR ", "") | L20: =IF(AND(F20="No", 'P1 Threshold Analysis'!D5="Yes"), 4, IF(AND(F20="No", 'P1 Threshold Analysis'!D5="No"),3,"")) | M20: =IF(AND(F20="No", 'P1 Threshold Analysis'!D5="Yes"), 4, IF(AND(F20="No", 'P1 Threshold Analysis'!D5="No"),3,"")) | N20: =IF(OR(L20="", M20=""), "", IF(L20*M20>=10, IF(L20*M20<=16, "High Risk", ""), IF(L20*M20>=6, IF(L20*M20<=9, "Medium Risk", ""), IF(L20*M20>=2, IF(L20*M20<=4, "Low Risk", ""), IF(L20*M20=1, "Negligible", "")))))
B21: 7 | C21: Do data subjects have the right to object to the processing of their personal data for direct marketing, profiling, or automated processing when it is the sole basis for decisions that significantly affect them? | I21: =IF(F21="No", "Denying data subjects the right to object to processing for direct marketing, profiling, or automated decisions increases the risk of unlawful processing and legal actions, including fines. ", "") | J21: =IF(F21="No", " Violation of data subject rights - Rights to object Unlawful Processing - Unauthorized Processing of Personal Data ","") | K21: =IF(F21="No", " SEC. 34(b), IRR SEC. 25, DPA ", "") | L21: =IF(AND(F21="No", 'P1 Threshold Analysis'!D5="Yes"), 4, IF(AND(F21="No", 'P1 Threshold Analysis'!D5="No"),3,"")) | M21: =IF(AND(F21="No", 'P1 Threshold Analysis'!D5="Yes"), 4, IF(AND(F21="No", 'P1 Threshold Analysis'!D5="No"),3,"")) | N21: =IF(OR(L21="", M21=""), "", IF(L21*M21>=10, IF(L21*M21<=16, "High Risk", ""), IF(L21*M21>=6, IF(L21*M21<=9, "Medium Risk", ""), IF(L21*M21>=2, IF(L21*M21<=4, "Low Risk", ""), IF(L21*M21=1, "Negligible", "")))))
B22: Right to access
B23: 1 | C23: Does the data subject have the right to confirm if their personal data is being processed and access details about its processing? Check all applicable | I23: =IF(F23="No", "Denying data subjects the right to confirm if their personal data is being processed and access related details undermines their rights and could result in non-compliance with data protection laws. ", "") | J23: =IF(F23="No", " Violation of data subject rights - Right to access ","") | K23: =IF(F23="No", " SEC. 16(c), DPA ", "") | L23: =IF(AND(F23="No", 'P1 Threshold Analysis'!D5="Yes"), 4, IF(AND(F23="No", 'P1 Threshold Analysis'!D4="Yes"),3,"")) | M23: =IF(AND(F23="No", 'P1 Threshold Analysis'!D5="Yes"), 4, IF(AND(F23="No", 'P1 Threshold Analysis'!D4="Yes"),3,"")) | N23: =IF(OR(L23="", M23=""), "", IF(L23*M23>=10, IF(L23*M23<=16, "High Risk", ""), IF(L23*M23>=6, IF(L23*M23<=9, "Medium Risk", ""), IF(L23*M23>=2, IF(L23*M23<=4, "Low Risk", ""), IF(L23*M23=1, "Negligible", "")))))
C24: a. Content and categories of his or her personal data
C25: b. Sources from which personal data was obtained, if not collected from the data subject
C26: c. Purposes of processing
C27: d. Manner by which personal data were processed
C28: e. Automated processes using personal data as the sole basis for decisions that significantly impact the data subject (if applicable)
C29: f. Names and addresses of recipients of the personal data (if applicable)
C30: g. Date when his or her personal data were last accessed and modified | F30: FALSE
C31: h. Retention period
C32: i. Designation, name or identity, and address of the DPO
B33: Right to rectify (Excludes cases requiring a court order, government agency directive, or official legal process)
B34: 1 | C34: Does the data subject have the right to dispute inaccuracies in their personal data and have the PIC correct them within the reasonable time? | I34: =IF(F34="No", "Not allowing data subjects to dispute inaccuracies and correct their personal data within a reasonable time increases the risk of decisions based on incorrect information, leading to potential harm and non-compliance with data accuracy requirements.", "") | J34: =IF(F34="No", " Violation of data subject rights - Right to rectification Violation of general privacy principles – Accuracy ","") | K34: =IF(F34="No", " SEC. 16(d), DPA SEC. 11, DPA ", "") | L34: =IF(AND(F34="No", 'P1 Threshold Analysis'!D5="Yes"), 4, IF(AND(F34="No", 'P1 Threshold Analysis'!D4="Yes"),3,"")) | M34: =IF(AND(F34="No", 'P1 Threshold Analysis'!D5="Yes"), 4, IF(AND(F34="No", 'P1 Threshold Analysis'!D4="Yes"),3,"")) | N34: =IF(OR(L34="", M34=""), "", IF(L34*M34>=10, IF(L34*M34<=16, "High Risk", ""), IF(L34*M34>=6, IF(L34*M34<=9, "Medium Risk", ""), IF(L34*M34>=2, IF(L34*M34<=4, "Low Risk", ""), IF(L34*M34=1, "Negligible", "")))))
B35: 2 | C35: If personal data has been corrected,
C36: a. Does the PIC ensure that both the new and retracted information are accessible and received simultaneously by the intended recipients? | I36: =IF(OR(F36="No", F37="No"), "Failing to ensure that both corrected and retracted personal data are promptly shared with intended recipients increases the risk of data inconsistencies, leading to potential miscommunication or incorrect decision-making. ", "") | J36: =IF(OR(F36="No", F37="No"), " Violation of data subject rights - Right to rectification Violation of general privacy principles – Accuracy ","") | K36: =IF(OR(F36="No", F37="No"), " SEC. 16(d), DPA SEC. 11, DPA ", "") | L36: =IF(AND(OR(F36="No", F37="No"), 'P1 Threshold Analysis'!D5="Yes"), 4, IF(AND(OR(F36="No", F37="No"), 'P1 Threshold Analysis'!D4="Yes"), 3, "")) | M36: =IF(AND(OR(F36="No", F37="No"), 'P1 Threshold Analysis'!D5="Yes"), 4, IF(AND(OR(F36="No", F37="No"), 'P1 Threshold Analysis'!D4="Yes"), 3, "")) | N36: =IF(OR(L36="", M36=""), "", IF(L36*M36>=10, IF(L36*M36<=16, "High Risk", ""), IF(L36*M36>=6, IF(L36*M36<=9, "Medium Risk", ""), IF(L36*M36>=2, IF(L36*M36<=4, "Low Risk", ""), IF(L36*M36=1, "Negligible", ""))))) | AZ36: Failing to ensure that both corrected and retracted personal data are promptly shared with intended recipients increases the risk of data inconsistencies, leading to potential miscommunication or incorrect decision-making. Not informing recipients or third parties about corrected inaccuracies in personal data creates a risk of continued misuse or reliance on outdated information, violating data accuracy principles.
C37: b. Does the PIC inform recipients or third parties who previously received the inaccurate personal data about its inaccuracy and subsequent correction? | I37: =IF(OR(F36="No", F37="No"), "Not informing recipients or third parties about corrected inaccuracies in personal data creates a risk of continued misuse or reliance on outdated information, violating data accuracy principles. ", "") | L37: =IF(AND(OR(F36="No", F37="No"), 'P1 Threshold Analysis'!D5="Yes"), 4, IF(AND(OR(F36="No", F37="No"), 'P1 Threshold Analysis'!D4="Yes"), 3, "")) | M37: =IF(AND(OR(F36="No", F37="No"), 'P1 Threshold Analysis'!D5="Yes"), 4, IF(AND(OR(F36="No", F37="No"), 'P1 Threshold Analysis'!D4="Yes"), 3, "")) | N37: =IF(OR(L37="", M37=""), "", IF(L37*M37>=10, IF(L37*M37<=16, "High Risk", ""), IF(L37*M37>=6, IF(L37*M37<=9, "Medium Risk", ""), IF(L37*M37>=2, IF(L37*M37<=4, "Low Risk", ""), IF(L37*M37=1, "Negligible", "")))))
B38: Right to erasure or blocking
B39: 1 | C39: Does the data subject have the right to request the suspension, withdrawal, blocking, removal, or destruction of their personal data from the PIC’s live and backup systems upon discovery and substantial proof of the following? Note: Personal data is: a. Incomplete, outdated, false, or unlawfully obtained b. Used for unauthorized purpose c. No longer necessary for the purpose for which they were collected d. Prejudicial to the data subject, unless justified by freedom of speech, of expression, or of the press, or otherwise authorized | I39: =IF(F39="No", "Denying data subjects the right to request suspension or deletion of their personal data limits their control over their information and exposes the organization to non-compliance with data protection and retention obligations.", "") | J39: =IF(F39="No", " Violation of data subject rights - Right to erasure or blocking ","") | K39: =IF(F39="No", " SEC. 16(e), DPA ", "") | L39: =IF(AND(F39="No", 'P1 Threshold Analysis'!D5="Yes"), 4, IF(AND(F39="No", 'P1 Threshold Analysis'!D4="Yes"),3,"")) | M39: =IF(AND(F39="No", 'P1 Threshold Analysis'!D5="Yes"), 4, IF(AND(F39="No", 'P1 Threshold Analysis'!D4="Yes"),3,"")) | N39: =IF(OR(L39="", M39=""), "", IF(L39*M39>=10, IF(L39*M39<=16, "High Risk", ""), IF(L39*M39>=6, IF(L39*M39<=9, "Medium Risk", ""), IF(L39*M39>=2, IF(L39*M39<=4, "Low Risk", ""), IF(L39*M39=1, "Negligible", "")))))
B40: Right to data portability (Applicable if processing is based on consent or contract AND processed electronically)
B41: 1 | C41: Does the data subject have the right to obtain a copy of their personal data from the PIC and have it transmitted to another PIC in a commonly used, structured, and electronic format? | I41: =IF(F41="No", "The lack of a process to provide data subjects with their personal data in a portable, structured format increases the risk of non-compliance with data portability requirements and limits data subjects' control over their data. ", "") | J41: =IF(F41="No", " Violation of data subject rights - Right to data portability ","") | K41: =IF(F41="No", " SEC. 18, DPA ", "") | L41: =IF(AND(F41="No", 'P1 Threshold Analysis'!D5="Yes"), 4, IF(AND(F41="No", 'P1 Threshold Analysis'!D4="Yes"),3,"")) | M41: =IF(AND(F41="No", 'P1 Threshold Analysis'!D5="Yes"), 4, IF(AND(F41="No", 'P1 Threshold Analysis'!D4="Yes"),3,"")) | N41: =IF(OR(L41="", M41=""), "", IF(L41*M41>=10, IF(L41*M41<=16, "High Risk", ""), IF(L41*M41>=6, IF(L41*M41<=9, "Medium Risk", ""), IF(L41*M41>=2, IF(L41*M41<=4, "Low Risk", ""), IF(L41*M41=1, "Negligible", "")))))
B42: Right to file a complaint / damages
...

Sheet P3 Data Security
B2: Organizational Security
B3: No. | C3: Questions | F3: Yes/No/N/A | H3: Response | I3: Threats/Vulnerabilities | J3: Risk | K3: Legal Basis | L3: Impact | M3: Probability | N3: Risk Rating
B4: 1 | C4: Have you appointed and registered a data protection officer (DPO) with the National Privacy Commission (NPC)? | I4: =IF(F4="No", "The absence of a registered DPO exposes the organization to a lack of oversight and accountability in managing data protection practices, increasing the risk of non-compliance with privacy regulations and potential legal penalties.", "") | J4: =IF(F4="No", "Failure to implement reasonable and appropriate security measures - Organizational ","") | K4: =IF(F4="No", "SEC. 20, DPA", "") | L4: =IF(AND(F4="No", 'P1 Threshold Analysis'!D5="Yes"), 4, IF(AND(F4="No", 'P1 Threshold Analysis'!D4="Yes"),3,"")) | M4: =IF(AND(F4="No", 'P1 Threshold Analysis'!D5="Yes"), 4, IF(AND(F4="No", 'P1 Threshold Analysis'!D4="Yes"),3,"")) | N4: =IF(OR(L4="", M4=""), "", IF(L4*M4>=10, IF(L4*M4<=16, "High Risk", ""), IF(L4*M4>=6, IF(L4*M4<=9, "Medium Risk", ""), IF(L4*M4>=2, IF(L4*M4<=4, "Low Risk", ""), IF(L4*M4=1, "Negligible", "")))))
B5: 2 | C5: Have you registered this project or system with the NPC? | I5: =IF(F5="No", "Failure to register the project or system with the NPC makes the organization non-compliant, risking administrative fines. ", "") | J5: =IF(F5="No", "Failure to implement reasonable and appropriate security measures – Organizational Failure to register the data processing system ","") | K5: =IF(F5="No", "SEC 20, DPA SEC. 24, DPA ", "") | L5: =IF(AND(F5="No", 'P1 Threshold Analysis'!D5="Yes"), 4, IF(AND(F5="No", 'P1 Threshold Analysis'!D4="Yes"),3,"")) | M5: =IF(AND(F5="No", 'P1 Threshold Analysis'!D5="Yes"), 4, IF(AND(F5="No", 'P1 Threshold Analysis'!D4="Yes"),3,"")) | N5: =IF(OR(L5="", M5=""), "", IF(L5*M5>=10, IF(L5*M5<=16, "High Risk", ""), IF(L5*M5>=6, IF(L5*M5<=9, "Medium Risk", ""), IF(L5*M5>=2, IF(L5*M5<=4, "Low Risk", ""), IF(L5*M5=1, "Negligible", "")))))
B6: 3 | C6: Do you have an inventory of this project or system? Check all present | I6: =IF(F6="No", "The absence of an inventory for a project or system prevents the organization from effectively managing personal data processing activities, increasing the risk of unauthorized access, data breaches, and non-compliance with data protection laws.", "") | J6: =IF(F6="No", "Failure to implement reasonable and appropriate security measures – Organizational Personal Data Breach - Availability ","") | K6: =IF(F6="No", "SEC 20, DPA ", "") | L6: =IF(AND(F6="No", COUNTIF(F7:G11, "False")>4), 4, IF(AND(F6="No", 'P1 Threshold Analysis'!D5="Yes", COUNTIF(F7:G11, "True")>0), 4, IF(AND(F6="No", 'P1 Threshold Analysis'!D5="No",COUNTIF(F7:G11, "True")>0), 3, ""))) | M6: =IF(AND(F6="No", COUNTIF(F7:G11, "False")>4), 4, IF(AND(F6="No", 'P1 Threshold Analysis'!D5="Yes", COUNTIF(F7:G11, "True")>0), 4, IF(AND(F6="No", 'P1 Threshold Analysis'!D5="No",COUNTIF(F7:G11, "True")>0), 3, ""))) | N6: =IF(OR(L6="", M6=""), "", IF(L6*M6>=10, IF(L6*M6<=16, "High Risk", ""), IF(L6*M6>=6, IF(L6*M6<=9, "Medium Risk", ""), IF(L6*M6>=2, IF(L6*M6<=4, "Low Risk", ""), IF(L6*M6=1, "Negligible", ""))))) | AZ6: The absence of an inventory for the project or system prevents the organization from effectively managing and monitoring personal data processing activities, increasing the risk of unauthorized access, data breaches, and non-compliance with data protection laws.
C7: a. Purpose of processing of personal data, including future processing or data sharing. | F7: FALSE
C8: b. Categories of data subjects, personal data, and recipients involved. | F8: FALSE
C9: c. Data flow from collection to disposal, including retention periods. | F9: FALSE
C10: d. Security measures (organizational, physical, and technical) | F10: FALSE
C11: e. Contacts details of the PIC, joint controller (if applicable), representative, and compliance officer or DPO. | F11: FALSE
B12: 4 | C12: Do you conduct a PIA for this project or system annually and update it when necessary (e.g., new features, major changes, new regulations, new contracts entered), considering the minimum requirements? Check all present | I12: =IF(F12="No", "Not conducting an annual PIA or updating it as needed increases the likelihood of overlooking new risks, vulnerabilities, or changes in processing activities, potentially leading to non-compliance and inadequate protection of personal data. ", "") | J12: =IF(F12="No", "Failure to implement reasonable and appropriate security measures – Organizational ","") | K12: =IF(F12="No", "SEC. 20, DPA ", "") | L12: =IF(AND(F12="No", COUNTIF(C14:H29, "False")>13), 4, IF(AND(F12="No", 'P1 Threshold Analysis'!D5="Yes", COUNTIF(C14:H29, "True")>0), 4, IF(AND(F12="No", 'P1 Threshold Analysis'!D5="No",COUNTIF(C14:H29, "True")>0), 3, ""))) | M12: =IF(AND(F12="No", COUNTIF(C14:H29, "False")>13), 4, IF(AND(F12="No", 'P1 Threshold Analysis'!D5="Yes", COUNTIF(C14:H29, "True")>0), 4, IF(AND(F12="No", 'P1 Threshold Analysis'!D5="No",COUNTIF(C14:H29, "True")>0), 3, ""))) | N12: =IF(OR(L12="", M12=""), "", IF(L12*M12>=10, IF(L12*M12<=16, "High Risk", ""), IF(L12*M12>=6, IF(L12*M12<=9, "Medium Risk", ""), IF(L12*M12>=2, IF(L12*M12<=4, "Low Risk", ""), IF(L12*M12=1, "Negligible", "")))))
C13: a. Data inventory
C14: i. Types and volume of personal data held, including employee records | F14: FALSE
C15: ii. List and location of repositories of personal data | F15: FALSE
C16: iii. Storage media used | F16: FALSE
C17: iv. Risks associated with data processing | F17: FALSE
C18: v. Processing operations across the data lifecycle, from collection to disposal | F18: FALSE
C19: b. Systematic Description | F19: FALSE
C20: c. Assessment of:
C21: i. General Data Privacy Principles | F21: FALSE
C22: ii. Rights and freedoms of a data subject | F22: FALSE
C23: iii. Data Security/confidentiality, integrity, and availability | F23: FALSE
C24: d. Risks identified are addressed by a Control Framework
C25: i. Nature of the personal data being protected | F25: FALSE
C26: ii. Risks from processing, organization size, and data volume | F26: FALSE
C27: iii. Industry best practices for data privacy | F27: FALSE
C28: iv. Cost of implementing security measures | F28: FALSE
C29: v. Purpose, scope, and risks of data sharing or outsourcing agreements | F29: FALSE
B30: 5 | C30: Are the personnel who process personal data under strict confidentiality if personal data are not intended for public disclosure (signing of NDAs)? | I30: =IF(F30="No", "Without strict confidentiality agreements (NDAs) in place, personnel may inadvertently disclose personal data, exposing the organization to data breaches and violating privacy obligations. ", "") | J30: =IF(F30="No", "Failure to implement reasonable and appropriate security measures – Organizational Personal Data Breach - Confidentiality ","") | K30: =IF(F30="No", "SEC. 20, DPA ", "") | L30: =IF(AND(F30="No", 'P1 Threshold Analysis'!D5="Yes"), 4, IF(AND(F30="No", 'P1 Threshold Analysis'!D4="Yes"),3,"")) | M30: =IF(AND(F30="No", 'P1 Threshold Analysis'!D5="Yes"), 4, IF(AND(F30="No", 'P1 Threshold Analysis'!D4="Yes"),3,"")) | N30: =IF(OR(L30="", M30=""), "", IF(L30*M30>=10, IF(L30*M30<=16, "High Risk", ""), IF(L30*M30>=6, IF(L30*M30<=9, "Medium Risk", ""), IF(L30*M30>=2, IF(L30*M30<=4, "Low Risk", ""), IF(L30*M30=1, "Negligible", "")))))
B31: 6 | C31: Do you periodically train employees, agents, personnel, or representatives on privacy and data protection policies? | I31: =IF(F31="No", "The lack of periodic training on privacy and data protection policies increases the risk of employees inadvertently violating data protection regulations or mishandling personal data, potentially leading to data breaches or non-compliance.", "") | J31: =IF(F31="No", "Failure to implement reasonable and appropriate security measures – Organizational ","") | K31: =IF(F31="No", "SEC. 20, DPA ", "") | L31: =IF(AND(F31="No", 'P1 Threshold Analysis'!D5="Yes"), 4, IF(AND(F31="No", 'P1 Threshold Analysis'!D4="Yes"),3,"")) | M31: =IF(AND(F31="No", 'P1 Threshold Analysis'!D5="Yes"), 4, IF(AND(F31="No", 'P1 Threshold Analysis'!D4="Yes"),3,"")) | N31: =IF(OR(L31="", M31=""), "", IF(L31*M31>=10, IF(L31*M31<=16, "High Risk", ""), IF(L31*M31>=6, IF(L31*M31<=9, "Medium Risk", ""), IF(L31*M31>=2, IF(L31*M31<=4, "Low Risk", ""), IF(L31*M31=1, "Negligible", "")))))
B32: 7 | C32: Do you have a Privacy Management Program (PMP) in place that considers the following? Check all present | I32: =IF(F32="No", "The absence of a PMP leaves the organization without a structured approach to ensure ongoing compliance, risk mitigation, and effective handling of personal data, increasing the likelihood of non-compliance and privacy violations.", "") | J32: =IF(F32="No", "Failure to implement reasonable and appropriate security measures – Organizational ","") | K32: =IF(F32="No", "SEC. 20, DPA ", "") | L32: =IF(AND(F32="No", COUNTIF(C34:H50, "False")>14), 4, IF(AND(F32="No", 'P1 Threshold Analysis'!D5="Yes", COUNTIF(C34:H50, "True")>0), 4, IF(AND(F32="No", 'P1 Threshold Analysis'!D5="No",COUNTIF(C34:H50, "True")>0), 3, ""))) | M32: =IF(AND(F32="No", COUNTIF(C34:H50, "False")>14), 4, IF(AND(F32="No", 'P1 Threshold Analysis'!D5="Yes", COUNTIF(C34:H50, "True")>0), 4, IF(AND(F32="No", 'P1 Threshold Analysis'!D5="No",COUNTIF(C34:H50, "True")>0), 3, ""))) | N32: =IF(OR(L32="", M32=""), "", IF(L32*M32>=10, IF(L32*M32<=16, "High Risk", ""), IF(L32*M32>=6, IF(L32*M32<=9, "Medium Risk", ""), IF(L32*M32>=2, IF(L32*M32<=4, "Low Risk", ""), IF(L32*M32=1, "Negligible", "")))))
C33: a. Organizational Commitment and leadership in data privacy.
C34: i. Management Buy-In | F34: FALSE
C35: ii. Data Protection Officer | F35: FALSE
C36: iii. Reporting Mechanisms | F36: FALSE
C37: b. Control Framework for developing privacy policies and implementing data protection measures.
C38: iv. Records of Processing Activities (RoPA) | F38: FALSE
C39: v. Risk Assessment | F39: FALSE
C40: vi. Registration | F40: FALSE
C41: vii. Policies and Procedures | F41: FALSE
...

Sheet P3 Cross-border Data Flows
B2: (Optional) Cross-border Data Flows
B3: Is there any cross-border transfer of data?
B4: No. | C4: Questions | F4: Yes/No/N/A | H4: Response | I4: Threats/Vulnerabilities | J4: Risk | K4: Legal Basis | L4: Impact | M4: Probability | N4: Risk Rating
B5: 1 | C5: Does the project or system transfer personal data to an organization or individual outside the Philippines, including cloud storage or data centers? Personal data will only be transferred to someone outside of the Philippines if any of the following apply: Check all applicable | F5: No | I5: =IF(F5="No", "Transferring personal data abroad without a lawful basis may lead to unauthorized processing, data breaches, and legal penalties under data protection laws.", "") -> Transferring personal data abroad without a lawful basis may lead to unauthorized processing, data breaches, and legal penalties under data protection laws. | J5: =IF(F5="No", "Unlawful Processing - Unauthorized Processing of Personal Data Unlawful Processing - Unauthorized Disclosure ","") -> Unlawful Processing - Unauthorized Processing of Personal Data Unlawful Processing - Unauthorized Disclosure | K5: =IF(F5="No", "SEC. 25, DPA SEC. 32, DPA ", "") -> SEC. 25, DPA SEC. 32, DPA | L5: =IF(AND(F5="No", 'P1 Threshold Analysis'!D5="Yes"), 4, IF(AND(F5="No", 'P1 Threshold Analysis'!D4="Yes"),3,"")) | M5: =IF(AND(F5="No", 'P1 Threshold Analysis'!D5="Yes"), 4, IF(AND(F5="No", 'P1 Threshold Analysis'!D4="Yes"),3,"")) | N5: =IF(OR(L5="", M5=""), "", IF(L5*M5>=10, IF(L5*M5<=16, "High Risk", ""), IF(L5*M5>=6, IF(L5*M5<=9, "Medium Risk", ""), IF(L5*M5>=2, IF(L5*M5<=4, "Low Risk", ""), IF(L5*M5=1, "Negligible", "")))))
C6: a. The individual consents to the transfer | F6: FALSE
C7: b. The recipients is subject to laws or a contract enforcing information handling principles similar to the DPA of 2012. | F7: FALSE
C8: c. The transfer is necessary to fulfill a contract between the individual and the organization. | F8: FALSE
C9: d. The transfer is required for a contract in the individual’s interest between the organization and a third party | F9: FALSE
C10: e. The transfer benefits the individual. | F10: FALSE
B11: 2 | C11: Has the organization taken reasonable steps to ensure that transferred data is stored, used, disclosed, and processed in compliance with the DPA of 2012? Check all present | I11: =IF(F11="No", "Failure to ensure that cross-border data transfers comply with the Data Privacy Act of 2012 increases the risk of personal data being misused or accessed without authorization and exposes the organization to regulatory sanctions for non-compliance.", "") | J11: =IF(F11="No", "Failure to implement reasonable and appropriate security measures – Organizational Failure to ensure that third parties implement security measures Personal Data Breach - Availability, Integrity, Confidentiality ","") | K11: =IF(F11="No", "SEC. 20, DPA ", "") | L11: =IF(AND(F11="No", COUNTIF(F12:G16, "False")>4), 4, IF(AND(F11="No", 'P1 Threshold Analysis'!D5="Yes", COUNTIF(F12:G16, "True")>0), 4, IF(AND(F11="No", 'P1 Threshold Analysis'!D5="No",COUNTIF(F12:G16, "True")>0), 3, ""))) | M11: =IF(AND(F11="No", COUNTIF(F12:G16, "False")>4), 4, IF(AND(F11="No", 'P1 Threshold Analysis'!D5="Yes", COUNTIF(F12:G16, "True")>0), 4, IF(AND(F11="No", 'P1 Threshold Analysis'!D5="No",COUNTIF(F12:G16, "True")>0), 3, ""))) | N11: =IF(OR(L11="", M11=""), "", IF(L11*M11>=10, IF(L11*M11<=16, "High Risk", ""), IF(L11*M11>=6, IF(L11*M11<=9, "Medium Risk", ""), IF(L11*M11>=2, IF(L11*M11<=4, "Low Risk", ""), IF(L11*M11=1, "Negligible", "")))))
C12: a. Data Transfer Security (e.g., lawful basis, data sharing/outsourcing agreements, secure transmission methods – TLS 1.2/1.3, VPN, data minimization) | F12: FALSE
C13: b. Data Storage & Protection (e.g., encryption of data at rest/AES-256, access control & role-based permissions, secure physical & cloud storage, data retention & disposal policies) | F13: FALSE
C14: c. Data Usage & Processing Compliance (e.g., purpose limitation, regular data processing audit, anonymization & pseudonymization, consent management) | F14: FALSE
C15: d. Data Disclosure Controls (e.g., strict third-party sharing rules, confidentiality agreements, data subject access & correction rights, data breach notification procedures) | F15: FALSE
C16: e. Compliance, Monitoring & Awareness (e.g., PIA, appointment of a DPO, Employee Privacy Training, Incident Response Plan) | F16: FALSE

Sheet Risk Treatment Plan
B2: Observation (Threat/Vulnerability) | C2: Risk | D2: Inherent Risk | E2: Risk Treatment | F2: Mitigation Measure | G2: Status | H2: Residual Risk Rating | I2: Control Reference | J2: Start Date | K2: Completion Date | L2: Review Frequency | M2: Risk Owner
